Workbook
Name FIN: القوائم!$H$2:$H$2
Name RAW: القوائم!$I$2:$I$5
Name TRN: القوائم!$J$2:$J$4

Sheet إدخال وسجل المنتجات
A1: مطعم بينو — سجل المنتجات والإدخال الذكي (تكويد تلقائي + ترجمة)
A2: ="منتج نهائي: "&COUNTIF($D$5:$D$590,"منتج نهائي") -> منتج نهائي: 109 | D2: ="مواد تحويلية: "&COUNTIF($D$5:$D$590,"مواد تحويلية") -> مواد تحويلية: 50 | F2: ="مواد خام: "&COUNTIF($D$5:$D$590,"مواد خام") -> مواد خام: 278
A3: اكتب الاسم (عربي) واختر النوع؛ الإنجليزي يظهر تلقائيًا من قاموس الترجمة، والكود تلقائي. النهائي حالته «جاهز للبيع». | E3: =HYPERLINK("#'إدخال وسجل المنتجات'!A156","📋 عرض كل الأصناف المسجّلة ("&(COUNTA($B$5:$B$154)+COUNTA($B$157:$B$590))&") ⤵") -> 📋 عرض كل الأصناف المسجّلة (435) ⤵
A4: م | B4: اسم المنتج (عربي) | C4: اسم المنتج (English) | D4: نوع المنتج | E4: حالة المنتج | F4: الكود (تلقائي) | G4: وحدة القياس | R4: السعرات الحرارية | S4: حجم الحصة (جم) | T4: سعرات / جرام | U4: وزن الوحدة (كجم)
A5: =IF($B5="","",COUNTA($B$5:$B5)) | C5: =IF($B5="","",IFERROR(VLOOKUP($B5,'قاموس الترجمة'!$A$2:$B$979,2,0),"")) | D5: مواد خام | E5: =IF($D5="منتج نهائي","جاهز للبيع","") | F5: =IF($B5="","",IF($K5<>"",$K5,IF($H5="","— اختر النوع —",IF(AND($H5<>"FIN",$I5=""),"— اختر الحالة —",$H5&"-"&$I5&"-"&TEXT(SUMPRODUCT(MAX(($H$157:$H$590=$H5)*($I$157:$I$590=$I5)*$J$157:$J$590))+SUMPRODUCT(($H$5:$H5=$H5)*($I$5:$I5=$I5)*($L$5:$L5=1)),"000"))))) | G5: وحدة | H5: =IFERROR(VLOOKUP($D5,القوائم!$A$2:$B$4,2,0),"") -> RAW | I5: =IF($H5="FIN","RTS",IF(ISNUMBER(SEARCH("مجمد",$E5)),"FRZ",IF(ISNUMBER(SEARCH("مبرد",$E5)),"CHL",IF(ISNUMBER(SEARCH("جاف",$E5)),"DRY",IF(ISNUMBER(SEARCH("استهلاك",$E5)),"CNS",IF(ISNUMBER(SEARCH("بيع",$E5)),"RTS","")))))) | K5: =IF($B5="","",IFERROR(INDEX($F$157:$F$590,MATCH($B5,$B$157:$B$590,0)),"")) | L5: =IF($B5="","",IF($K5="",1,0)) | M5: =IF($I5="","",COUNTIF($I$5:$I5,$I5)) | R5: 900 | S5: 300 | T5: =IF(OR($R5="",$S5="",$S5=0),"",ROUND($R5/$S5,2)) -> 3
A6: =IF($B6="","",COUNTA($B$5:$B6)) | C6: =IF($B6="","",IFERROR(VLOOKUP($B6,'قاموس الترجمة'!$A$2:$B$979,2,0),"")) | D6: مواد خام | E6: استهلاكي | F6: =IF($B6="","",IF($K6<>"",$K6,IF($H6="","— اختر النوع —",IF(AND($H6<>"FIN",$I6=""),"— اختر الحالة —",$H6&"-"&$I6&"-"&TEXT(SUMPRODUCT(MAX(($H$157:$H$590=$H6)*($I$157:$I$590=$I6)*$J$157:$J$590))+SUMPRODUCT(($H$5:$H6=$H6)*($I$5:$I6=$I6)*($L$5:$L6=1)),"000"))))) | G6: كيلو | H6: =IFERROR(VLOOKUP($D6,القوائم!$A$2:$B$4,2,0),"") -> RAW | I6: =IF($H6="FIN","RTS",IF(ISNUMBER(SEARCH("مجمد",$E6)),"FRZ",IF(ISNUMBER(SEARCH("مبرد",$E6)),"CHL",IF(ISNUMBER(SEARCH("جاف",$E6)),"DRY",IF(ISNUMBER(SEARCH("استهلاك",$E6)),"CNS",IF(ISNUMBER(SEARCH("بيع",$E6)),"RTS","")))))) -> CNS | K6: =IF($B6="","",IFERROR(INDEX($F$157:$F$590,MATCH($B6,$B$157:$B$590,0)),"")) | L6: =IF($B6="","",IF($K6="",1,0)) | M6: =IF($I6="","",COUNTIF($I$5:$I6,$I6)) -> 1 | T6: =IF(OR($R6="",$S6="",$S6=0),"",ROUND($R6/$S6,2))
A7: =IF($B7="","",COUNTA($B$5:$B7)) -> 1 | B7: طحين دبل زيرو | C7: =IF($B7="","",IFERROR(VLOOKUP($B7,'قاموس الترجمة'!$A$2:$B$979,2,0),"")) -> Flour Double Zero | D7: مواد خام | E7: تخزين جاف | F7: =IF($B7="","",IF($K7<>"",$K7,IF($H7="","— اختر النوع —",IF(AND($H7<>"FIN",$I7=""),"— اختر الحالة —",$H7&"-"&$I7&"-"&TEXT(SUMPRODUCT(MAX(($H$157:$H$590=$H7)*($I$157:$I$590=$I7)*$J$157:$J$590))+SUMPRODUCT(($H$5:$H7=$H7)*($I$5:$I7=$I7)*($L$5:$L7=1)),"000"))))) -> RAW-DRY-082 | G7: كيلو | H7: =IFERROR(VLOOKUP($D7,القوائم!$A$2:$B$4,2,0),"") -> RAW | I7: =IF($H7="FIN","RTS",IF(ISNUMBER(SEARCH("مجمد",$E7)),"FRZ",IF(ISNUMBER(SEARCH("مبرد",$E7)),"CHL",IF(ISNUMBER(SEARCH("جاف",$E7)),"DRY",IF(ISNUMBER(SEARCH("استهلاك",$E7)),"CNS",IF(ISNUMBER(SEARCH("بيع",$E7)),"RTS","")))))) -> DRY | K7: =IF($B7="","",IFERROR(INDEX($F$157:$F$590,MATCH($B7,$B$157:$B$590,0)),"")) -> RAW-DRY-082 | L7: =IF($B7="","",IF($K7="",1,0)) -> 0 | M7: =IF($I7="","",COUNTIF($I$5:$I7,$I7)) -> 1 | R7: 60 | S7: 100 | T7: =IF(OR($R7="",$S7="",$S7=0),"",ROUND($R7/$S7,2)) -> 0.6 | U7: 25
A8: =IF($B8="","",COUNTA($B$5:$B8)) | C8: =IF($B8="","",IFERROR(VLOOKUP($B8,'قاموس الترجمة'!$A$2:$B$979,2,0),"")) | E8: =IF($D8="منتج نهائي","جاهز للبيع","") | F8: =IF($B8="","",IF($K8<>"",$K8,IF($H8="","— اختر النوع —",IF(AND($H8<>"FIN",$I8=""),"— اختر الحالة —",$H8&"-"&$I8&"-"&TEXT(SUMPRODUCT(MAX(($H$157:$H$590=$H8)*($I$157:$I$590=$I8)*$J$157:$J$590))+SUMPRODUCT(($H$5:$H8=$H8)*($I$5:$I8=$I8)*($L$5:$L8=1)),"000"))))) | H8: =IFERROR(VLOOKUP($D8,القوائم!$A$2:$B$4,2,0),"") | I8: =IF($H8="FIN","RTS",IF(ISNUMBER(SEARCH("مجمد",$E8)),"FRZ",IF(ISNUMBER(SEARCH("مبرد",$E8)),"CHL",IF(ISNUMBER(SEARCH("جاف",$E8)),"DRY",IF(ISNUMBER(SEARCH("استهلاك",$E8)),"CNS",IF(ISNUMBER(SEARCH("بيع",$E8)),"RTS","")))))) | K8: =IF($B8="","",IFERROR(INDEX($F$157:$F$590,MATCH($B8,$B$157:$B$590,0)),"")) | L8: =IF($B8="","",IF($K8="",1,0)) | M8: =IF($I8="","",COUNTIF($I$5:$I8,$I8)) | T8: =IF(OR($R8="",$S8="",$S8=0),"",ROUND($R8/$S8,2))
A9: =IF($B9="","",COUNTA($B$5:$B9)) | C9: =IF($B9="","",IFERROR(VLOOKUP($B9,'قاموس الترجمة'!$A$2:$B$979,2,0),"")) | E9: =IF($D9="منتج نهائي","جاهز للبيع","") | F9: =IF($B9="","",IF($K9<>"",$K9,IF($H9="","— اختر النوع —",IF(AND($H9<>"FIN",$I9=""),"— اختر الحالة —",$H9&"-"&$I9&"-"&TEXT(SUMPRODUCT(MAX(($H$157:$H$590=$H9)*($I$157:$I$590=$I9)*$J$157:$J$590))+SUMPRODUCT(($H$5:$H9=$H9)*($I$5:$I9=$I9)*($L$5:$L9=1)),"000"))))) | H9: =IFERROR(VLOOKUP($D9,القوائم!$A$2:$B$4,2,0),"") | I9: =IF($H9="FIN","RTS",IF(ISNUMBER(SEARCH("مجمد",$E9)),"FRZ",IF(ISNUMBER(SEARCH("مبرد",$E9)),"CHL",IF(ISNUMBER(SEARCH("جاف",$E9)),"DRY",IF(ISNUMBER(SEARCH("استهلاك",$E9)),"CNS",IF(ISNUMBER(SEARCH("بيع",$E9)),"RTS","")))))) | K9: =IF($B9="","",IFERROR(INDEX($F$157:$F$590,MATCH($B9,$B$157:$B$590,0)),"")) | L9: =IF($B9="","",IF($K9="",1,0)) | M9: =IF($I9="","",COUNTIF($I$5:$I9,$I9)) | T9: =IF(OR($R9="",$S9="",$S9=0),"",ROUND($R9/$S9,2))
A10: =IF($B10="","",COUNTA($B$5:$B10)) | C10: =IF($B10="","",IFERROR(VLOOKUP($B10,'قاموس الترجمة'!$A$2:$B$979,2,0),"")) | E10: =IF($D10="منتج نهائي","جاهز للبيع","") | F10: =IF($B10="","",IF($K10<>"",$K10,IF($H10="","— اختر النوع —",IF(AND($H10<>"FIN",$I10=""),"— اختر الحالة —",$H10&"-"&$I10&"-"&TEXT(SUMPRODUCT(MAX(($H$157:$H$590=$H10)*($I$157:$I$590=$I10)*$J$157:$J$590))+SUMPRODUCT(($H$5:$H10=$H10)*($I$5:$I10=$I10)*($L$5:$L10=1)),"000"))))) | H10: =IFERROR(VLOOKUP($D10,القوائم!$A$2:$B$4,2,0),"") | I10: =IF($H10="FIN","RTS",IF(ISNUMBER(SEARCH("مجمد",$E10)),"FRZ",IF(ISNUMBER(SEARCH("مبرد",$E10)),"CHL",IF(ISNUMBER(SEARCH("جاف",$E10)),"DRY",IF(ISNUMBER(SEARCH("استهلاك",$E10)),"CNS",IF(ISNUMBER(SEARCH("بيع",$E10)),"RTS","")))))) | K10: =IF($B10="","",IFERROR(INDEX($F$157:$F$590,MATCH($B10,$B$157:$B$590,0)),"")) | L10: =IF($B10="","",IF($K10="",1,0)) | M10: =IF($I10="","",COUNTIF($I$5:$I10,$I10)) | T10: =IF(OR($R10="",$S10="",$S10=0),"",ROUND($R10/$S10,2))
A11: =IF($B11="","",COUNTA($B$5:$B11)) | C11: =IF($B11="","",IFERROR(VLOOKUP($B11,'قاموس الترجمة'!$A$2:$B$979,2,0),"")) | E11: =IF($D11="منتج نهائي","جاهز للبيع","") | F11: =IF($B11="","",IF($K11<>"",$K11,IF($H11="","— اختر النوع —",IF(AND($H11<>"FIN",$I11=""),"— اختر الحالة —",$H11&"-"&$I11&"-"&TEXT(SUMPRODUCT(MAX(($H$157:$H$590=$H11)*($I$157:$I$590=$I11)*$J$157:$J$590))+SUMPRODUCT(($H$5:$H11=$H11)*($I$5:$I11=$I11)*($L$5:$L11=1)),"000"))))) | H11: =IFERROR(VLOOKUP($D11,القوائم!$A$2:$B$4,2,0),"") | I11: =IF($H11="FIN","RTS",IF(ISNUMBER(SEARCH("مجمد",$E11)),"FRZ",IF(ISNUMBER(SEARCH("مبرد",$E11)),"CHL",IF(ISNUMBER(SEARCH("جاف",$E11)),"DRY",IF(ISNUMBER(SEARCH("استهلاك",$E11)),"CNS",IF(ISNUMBER(SEARCH("بيع",$E11)),"RTS","")))))) | K11: =IF($B11="","",IFERROR(INDEX($F$157:$F$590,MATCH($B11,$B$157:$B$590,0)),"")) | L11: =IF($B11="","",IF($K11="",1,0)) | M11: =IF($I11="","",COUNTIF($I$5:$I11,$I11)) | T11: =IF(OR($R11="",$S11="",$S11=0),"",ROUND($R11/$S11,2))
A12: =IF($B12="","",COUNTA($B$5:$B12)) | C12: =IF($B12="","",IFERROR(VLOOKUP($B12,'قاموس الترجمة'!$A$2:$B$979,2,0),"")) | E12: =IF($D12="منتج نهائي","جاهز للبيع","") | F12: =IF($B12="","",IF($K12<>"",$K12,IF($H12="","— اختر النوع —",IF(AND($H12<>"FIN",$I12=""),"— اختر الحالة —",$H12&"-"&$I12&"-"&TEXT(SUMPRODUCT(MAX(($H$157:$H$590=$H12)*($I$157:$I$590=$I12)*$J$157:$J$590))+SUMPRODUCT(($H$5:$H12=$H12)*($I$5:$I12=$I12)*($L$5:$L12=1)),"000"))))) | H12: =IFERROR(VLOOKUP($D12,القوائم!$A$2:$B$4,2,0),"") | I12: =IF($H12="FIN","RTS",IF(ISNUMBER(SEARCH("مجمد",$E12)),"FRZ",IF(ISNUMBER(SEARCH("مبرد",$E12)),"CHL",IF(ISNUMBER(SEARCH("جاف",$E12)),"DRY",IF(ISNUMBER(SEARCH("استهلاك",$E12)),"CNS",IF(ISNUMBER(SEARCH("بيع",$E12)),"RTS","")))))) | K12: =IF($B12="","",IFERROR(INDEX($F$157:$F$590,MATCH($B12,$B$157:$B$590,0)),"")) | L12: =IF($B12="","",IF($K12="",1,0)) | M12: =IF($I12="","",COUNTIF($I$5:$I12,$I12)) | T12: =IF(OR($R12="",$S12="",$S12=0),"",ROUND($R12/$S12,2))
A13: =IF($B13="","",COUNTA($B$5:$B13)) | C13: =IF($B13="","",IFERROR(VLOOKUP($B13,'قاموس الترجمة'!$A$2:$B$979,2,0),"")) | E13: =IF($D13="منتج نهائي","جاهز للبيع","") | F13: =IF($B13="","",IF($K13<>"",$K13,IF($H13="","— اختر النوع —",IF(AND($H13<>"FIN",$I13=""),"— اختر الحالة —",$H13&"-"&$I13&"-"&TEXT(SUMPRODUCT(MAX(($H$157:$H$590=$H13)*($I$157:$I$590=$I13)*$J$157:$J$590))+SUMPRODUCT(($H$5:$H13=$H13)*($I$5:$I13=$I13)*($L$5:$L13=1)),"000"))))) | H13: =IFERROR(VLOOKUP($D13,القوائم!$A$2:$B$4,2,0),"") | I13: =IF($H13="FIN","RTS",IF(ISNUMBER(SEARCH("مجمد",$E13)),"FRZ",IF(ISNUMBER(SEARCH("مبرد",$E13)),"CHL",IF(ISNUMBER(SEARCH("جاف",$E13)),"DRY",IF(ISNUMBER(SEARCH("استهلاك",$E13)),"CNS",IF(ISNUMBER(SEARCH("بيع",$E13)),"RTS","")))))) | K13: =IF($B13="","",IFERROR(INDEX($F$157:$F$590,MATCH($B13,$B$157:$B$590,0)),"")) | L13: =IF($B13="","",IF($K13="",1,0)) | M13: =IF($I13="","",COUNTIF($I$5:$I13,$I13)) | T13: =IF(OR($R13="",$S13="",$S13=0),"",ROUND($R13/$S13,2))
A14: =IF($B14="","",COUNTA($B$5:$B14)) | C14: =IF($B14="","",IFERROR(VLOOKUP($B14,'قاموس الترجمة'!$A$2:$B$979,2,0),"")) | E14: =IF($D14="منتج نهائي","جاهز للبيع","") | F14: =IF($B14="","",IF($K14<>"",$K14,IF($H14="","— اختر النوع —",IF(AND($H14<>"FIN",$I14=""),"— اختر الحالة —",$H14&"-"&$I14&"-"&TEXT(SUMPRODUCT(MAX(($H$157:$H$590=$H14)*($I$157:$I$590=$I14)*$J$157:$J$590))+SUMPRODUCT(($H$5:$H14=$H14)*($I$5:$I14=$I14)*($L$5:$L14=1)),"000"))))) | H14: =IFERROR(VLOOKUP($D14,القوائم!$A$2:$B$4,2,0),"") | I14: =IF($H14="FIN","RTS",IF(ISNUMBER(SEARCH("مجمد",$E14)),"FRZ",IF(ISNUMBER(SEARCH("مبرد",$E14)),"CHL",IF(ISNUMBER(SEARCH("جاف",$E14)),"DRY",IF(ISNUMBER(SEARCH("استهلاك",$E14)),"CNS",IF(ISNUMBER(SEARCH("بيع",$E14)),"RTS","")))))) | K14: =IF($B14="","",IFERROR(INDEX($F$157:$F$590,MATCH($B14,$B$157:$B$590,0)),"")) | L14: =IF($B14="","",IF($K14="",1,0)) | M14: =IF($I14="","",COUNTIF($I$5:$I14,$I14)) | T14: =IF(OR($R14="",$S14="",$S14=0),"",ROUND($R14/$S14,2))
A15: =IF($B15="","",COUNTA($B$5:$B15)) | C15: =IF($B15="","",IFERROR(VLOOKUP($B15,'قاموس الترجمة'!$A$2:$B$979,2,0),"")) | E15: =IF($D15="منتج نهائي","جاهز للبيع","") | F15: =IF($B15="","",IF($K15<>"",$K15,IF($H15="","— اختر النوع —",IF(AND($H15<>"FIN",$I15=""),"— اختر الحالة —",$H15&"-"&$I15&"-"&TEXT(SUMPRODUCT(MAX(($H$157:$H$590=$H15)*($I$157:$I$590=$I15)*$J$157:$J$590))+SUMPRODUCT(($H$5:$H15=$H15)*($I$5:$I15=$I15)*($L$5:$L15=1)),"000"))))) | H15: =IFERROR(VLOOKUP($D15,القوائم!$A$2:$B$4,2,0),"") | I15: =IF($H15="FIN","RTS",IF(ISNUMBER(SEARCH("مجمد",$E15)),"FRZ",IF(ISNUMBER(SEARCH("مبرد",$E15)),"CHL",IF(ISNUMBER(SEARCH("جاف",$E15)),"DRY",IF(ISNUMBER(SEARCH("استهلاك",$E15)),"CNS",IF(ISNUMBER(SEARCH("بيع",$E15)),"RTS","")))))) | K15: =IF($B15="","",IFERROR(INDEX($F$157:$F$590,MATCH($B15,$B$157:$B$590,0)),"")) | L15: =IF($B15="","",IF($K15="",1,0)) | M15: =IF($I15="","",COUNTIF($I$5:$I15,$I15)) | T15: =IF(OR($R15="",$S15="",$S15=0),"",ROUND($R15/$S15,2))
A16: =IF($B16="","",COUNTA($B$5:$B16)) | C16: =IF($B16="","",IFERROR(VLOOKUP($B16,'قاموس الترجمة'!$A$2:$B$979,2,0),"")) | E16: =IF($D16="منتج نهائي","جاهز للبيع","") | F16: =IF($B16="","",IF($K16<>"",$K16,IF($H16="","— اختر النوع —",IF(AND($H16<>"FIN",$I16=""),"— اختر الحالة —",$H16&"-"&$I16&"-"&TEXT(SUMPRODUCT(MAX(($H$157:$H$590=$H16)*($I$157:$I$590=$I16)*$J$157:$J$590))+SUMPRODUCT(($H$5:$H16=$H16)*($I$5:$I16=$I16)*($L$5:$L16=1)),"000"))))) | H16: =IFERROR(VLOOKUP($D16,القوائم!$A$2:$B$4,2,0),"") | I16: =IF($H16="FIN","RTS",IF(ISNUMBER(SEARCH("مجمد",$E16)),"FRZ",IF(ISNUMBER(SEARCH("مبرد",$E16)),"CHL",IF(ISNUMBER(SEARCH("جاف",$E16)),"DRY",IF(ISNUMBER(SEARCH("استهلاك",$E16)),"CNS",IF(ISNUMBER(SEARCH("بيع",$E16)),"RTS","")))))) | K16: =IF($B16="","",IFERROR(INDEX($F$157:$F$590,MATCH($B16,$B$157:$B$590,0)),"")) | L16: =IF($B16="","",IF($K16="",1,0)) | M16: =IF($I16="","",COUNTIF($I$5:$I16,$I16)) | T16: =IF(OR($R16="",$S16="",$S16=0),"",ROUND($R16/$S16,2))
A17: =IF($B17="","",COUNTA($B$5:$B17)) | C17: =IF($B17="","",IFERROR(VLOOKUP($B17,'قاموس الترجمة'!$A$2:$B$979,2,0),"")) | E17: =IF($D17="منتج نهائي","جاهز للبيع","") | F17: =IF($B17="","",IF($K17<>"",$K17,IF($H17="","— اختر النوع —",IF(AND($H17<>"FIN",$I17=""),"— اختر الحالة —",$H17&"-"&$I17&"-"&TEXT(SUMPRODUCT(MAX(($H$157:$H$590=$H17)*($I$157:$I$590=$I17)*$J$157:$J$590))+SUMPRODUCT(($H$5:$H17=$H17)*($I$5:$I17=$I17)*($L$5:$L17=1)),"000"))))) | H17: =IFERROR(VLOOKUP($D17,القوائم!$A$2:$B$4,2,0),"") | I17: =IF($H17="FIN","RTS",IF(ISNUMBER(SEARCH("مجمد",$E17)),"FRZ",IF(ISNUMBER(SEARCH("مبرد",$E17)),"CHL",IF(ISNUMBER(SEARCH("جاف",$E17)),"DRY",IF(ISNUMBER(SEARCH("استهلاك",$E17)),"CNS",IF(ISNUMBER(SEARCH("بيع",$E17)),"RTS","")))))) | K17: =IF($B17="","",IFERROR(INDEX($F$157:$F$590,MATCH($B17,$B$157:$B$590,0)),"")) | L17: =IF($B17="","",IF($K17="",1,0)) | M17: =IF($I17="","",COUNTIF($I$5:$I17,$I17)) | T17: =IF(OR($R17="",$S17="",$S17=0),"",ROUND($R17/$S17,2))
A18: =IF($B18="","",COUNTA($B$5:$B18)) | C18: =IF($B18="","",IFERROR(VLOOKUP($B18,'قاموس الترجمة'!$A$2:$B$979,2,0),"")) | E18: =IF($D18="منتج نهائي","جاهز للبيع","") | F18: =IF($B18="","",IF($K18<>"",$K18,IF($H18="","— اختر النوع —",IF(AND($H18<>"FIN",$I18=""),"— اختر الحالة —",$H18&"-"&$I18&"-"&TEXT(SUMPRODUCT(MAX(($H$157:$H$590=$H18)*($I$157:$I$590=$I18)*$J$157:$J$590))+SUMPRODUCT(($H$5:$H18=$H18)*($I$5:$I18=$I18)*($L$5:$L18=1)),"000"))))) | H18: =IFERROR(VLOOKUP($D18,القوائم!$A$2:$B$4,2,0),"") | I18: =IF($H18="FIN","RTS",IF(ISNUMBER(SEARCH("مجمد",$E18)),"FRZ",IF(ISNUMBER(SEARCH("مبرد",$E18)),"CHL",IF(ISNUMBER(SEARCH("جاف",$E18)),"DRY",IF(ISNUMBER(SEARCH("استهلاك",$E18)),"CNS",IF(ISNUMBER(SEARCH("بيع",$E18)),"RTS","")))))) | K18: =IF($B18="","",IFERROR(INDEX($F$157:$F$590,MATCH($B18,$B$157:$B$590,0)),"")) | L18: =IF($B18="","",IF($K18="",1,0)) | M18: =IF($I18="","",COUNTIF($I$5:$I18,$I18)) | T18: =IF(OR($R18="",$S18="",$S18=0),"",ROUND($R18/$S18,2))
A19: =IF($B19="","",COUNTA($B$5:$B19)) | C19: =IF($B19="","",IFERROR(VLOOKUP($B19,'قاموس الترجمة'!$A$2:$B$979,2,0),"")) | E19: =IF($D19="منتج نهائي","جاهز للبيع","") | F19: =IF($B19="","",IF($K19<>"",$K19,IF($H19="","— اختر النوع —",IF(AND($H19<>"FIN",$I19=""),"— اختر الحالة —",$H19&"-"&$I19&"-"&TEXT(SUMPRODUCT(MAX(($H$157:$H$590=$H19)*($I$157:$I$590=$I19)*$J$157:$J$590))+SUMPRODUCT(($H$5:$H19=$H19)*($I$5:$I19=$I19)*($L$5:$L19=1)),"000"))))) | H19: =IFERROR(VLOOKUP($D19,القوائم!$A$2:$B$4,2,0),"") | I19: =IF($H19="FIN","RTS",IF(ISNUMBER(SEARCH("مجمد",$E19)),"FRZ",IF(ISNUMBER(SEARCH("مبرد",$E19)),"CHL",IF(ISNUMBER(SEARCH("جاف",$E19)),"DRY",IF(ISNUMBER(SEARCH("استهلاك",$E19)),"CNS",IF(ISNUMBER(SEARCH("بيع",$E19)),"RTS","")))))) | K19: =IF($B19="","",IFERROR(INDEX($F$157:$F$590,MATCH($B19,$B$157:$B$590,0)),"")) | L19: =IF($B19="","",IF($K19="",1,0)) | M19: =IF($I19="","",COUNTIF($I$5:$I19,$I19)) | T19: =IF(OR($R19="",$S19="",$S19=0),"",ROUND($R19/$S19,2))
... A154: =IF($B154="","",COUNTA($B$5:$B154)) | C154: =IF($B154="","",IFERROR(VLOOKUP($B154,'قاموس الترجمة'!$A$2:$B$979,2,0),"")) | E154: =IF($D154="منتج نهائي","جاهز للبيع","") | F154: =IF($B154="","",IF($K154<>"",$K154,IF($H154="","— اختر النوع —",IF(AND($H154<>"FIN",$I154=""),"— اختر الحالة —",$H154&"-"&$I154&"-"&TEXT(SUMPRODUCT(MAX(($H$157:$H$590=$H154)*($I$157:$I$590=$I154)*$J$157:$J$590))+SUMPRODUCT(($H$5:$H154=$H154)*($I$5:$I154=$I154)*($L$5:$L154=1)),"000"))))) | H154: =IFERROR(VLOOKUP($D154,القوائم!$A$2:$B$4,2,0),"") | I154: =IF($H154="FIN","RTS",IF(ISNUMBER(SEARCH("مجمد",$E154)),"FRZ",IF(ISNUMBER(SEARCH("مبرد",$E154)),"CHL",IF(ISNUMBER(SEARCH("جاف",$E154)),"DRY",IF(ISNUMBER(SEARCH("استهلاك",$E154)),"CNS",IF(ISNUMBER(SEARCH("بيع",$E154)),"RTS","")))))) | K154: =IF($B154="","",IFERROR(INDEX($F$157:$F$590,MATCH($B154,$B$157:$B$590,0)),"")) | L154: =IF($B154="","",IF($K154="",1,0)) | M154: =IF($I154="","",COUNTIF($I$5:$I154,$I154)) | T154: =IF(OR($R154="",$S154="",$S154=0),"",ROUND($R154/$S154,2))
A155: ▼ السجل الكامل (434) — عدّل أي صنف؛ يأخذ كودًا جديدًا عند تغيير تصنيفه دون المساس بباقي الأكواد ▼ | G155: =HYPERLINK("#'إدخال وسجل المنتجات'!A5","⬆ العودة للإدخال") -> ⬆ العودة للإدخال
A156: م | B156: اسم المنتج (عربي) | C156: اسم المنتج EN | D156: نوع المنتج | E156: حالة المنتج | F156: الكود | G156: وحدة القياس | R156: السعرات الحرارية | S156: حجم الحصة (جم) | T156: سعرات / جرام
A157: 1 | B157: احتفال اعياد ميلاد | C157: Birthday Celebration | D157: مواد خام | E157: استهلاكي | F157: =IF($H157="","",$H157&"-"&$I157&"-"&TEXT($J157,"000")) -> RAW-CNS-001 | G157: وحدة | H157: =IFERROR(VLOOKUP($D157,القوائم!$A$2:$B$4,2,0),"") -> RAW | I157: =IF($H157="FIN","RTS",IF(ISNUMBER(SEARCH("مجمد",$E157)),"FRZ",IF(ISNUMBER(SEARCH("مبرد",$E157)),"CHL",IF(ISNUMBER(SEARCH("جاف",$E157)),"DRY",IF(ISNUMBER(SEARCH("استهلاك",$E157)),"CNS",IF(ISNUMBER(SEARCH("بيع",$E157)),"RTS","")))))) -> CNS | J157: =IF($H157="","",IF($N157=0,$Q157,SUMPRODUCT(($O$157:$O$590=$H157)*($P$157:$P$590=$I157)*$Q$157:$Q$590)+COUNTIFS($H$157:$H157,$H157,$I$157:$I157,$I157,$N$157:$N157,1))) -> 1 | M157: =IF($I157="","",COUNTIF($I$5:$I157,$I157)) -> 2 | N157: =IF($H157="","",IF(OR($H157<>$O157,$I157<>$P157),1,0)) -> 0 | O157: RAW | P157: CNS | Q157: 1 | T157: =IF(OR($R157="",$S157="",$S157=0),"",ROUND($R157/$S157,2))
A158: 2 | B158: ارانشيني ترافل rozetto balls | C158: Truffle Rozetto Balls Arancini | D158: منتج نهائي | E158: جاهز للبيع | F158: =IF($H158="","",$H158&"-"&$I158&"-"&TEXT($J158,"000")) -> FIN-RTS-001 | G158: وحدة | H158: =IFERROR(VLOOKUP($D158,القوائم!$A$2:$B$4,2,0),"") -> FIN | I158: =IF($H158="FIN","RTS",IF(ISNUMBER(SEARCH("مجمد",$E158)),"FRZ",IF(ISNUMBER(SEARCH("مبرد",$E158)),"CHL",IF(ISNUMBER(SEARCH("جاف",$E158)),"DRY",IF(ISNUMBER(SEARCH("استهلاك",$E158)),"CNS",IF(ISNUMBER(SEARCH("بيع",$E158)),"RTS","")))))) -> RTS | J158: =IF($H158="","",IF($N158=0,$Q158,SUMPRODUCT(($O$157:$O$590=$H158)*($P$157:$P$590=$I158)*$Q$157:$Q$590)+COUNTIFS($H$157:$H158,$H158,$I$157:$I158,$I158,$N$157:$N158,1))) -> 1 | M158: =IF($I158="","",COUNTIF($I$5:$I158,$I158)) -> 1 | N158: =IF($H158="","",IF(OR($H158<>$O158,$I158<>$P158),1,0)) -> 0 | O158: FIN | P158: RTS | Q158: 1 | R158: 270 | S158: 100 | T158: =IF(OR($R158="",$S158="",$S158=0),"",ROUND($R158/$S158,2)) -> 2.7
A159: 3 | B159: ارانشيني عادي rozetto balls | C159: Rozetto Balls Arancini | D159: منتج نهائي | E159: جاهز للبيع | F159: =IF($H159="","",$H159&"-"&$I159&"-"&TEXT($J159,"000")) -> FIN-RTS-002 | G159: وحدة | H159: =IFERROR(VLOOKUP($D159,القوائم!$A$2:$B$4,2,0),"") -> FIN | I159: =IF($H159="FIN","RTS",IF(ISNUMBER(SEARCH("مجمد",$E159)),"FRZ",IF(ISNUMBER(SEARCH("مبرد",$E159)),"CHL",IF(ISNUMBER(SEARCH("جاف",$E159)),"DRY",IF(ISNUMBER(SEARCH("استهلاك",$E159)),"CNS",IF(ISNUMBER(SEARCH("بيع",$E159)),"RTS","")))))) -> RTS | J159: =IF($H159="","",IF($N159=0,$Q159,SUMPRODUCT(($O$157:$O$590=$H159)*($P$157:$P$590=$I159)*$Q$157:$Q$590)+COUNTIFS($H$157:$H159,$H159,$I$157:$I159,$I159,$N$157:$N159,1))) -> 2 | M159: =IF($I159="","",COUNTIF($I$5:$I159,$I159)) -> 2 | N159: =IF($H159="","",IF(OR($H159<>$O159,$I159<>$P159),1,0)) -> 0 | O159: FIN | P159: RTS | Q159: 2 | R159: 260 | S159: 100 | T159: =IF(OR($R159="",$S159="",$S159=0),"",ROUND($R159/$S159,2)) -> 2.6
A160: 4 | B160: ارانشيني rozetto balls | C160: Rozetto Balls Arancini | D160: منتج نهائي | E160: جاهز للبيع | F160: =IF($H160="","",$H160&"-"&$I160&"-"&TEXT($J160,"000")) -> FIN-RTS-003 | G160: وحدة | H160: =IFERROR(VLOOKUP($D160,القوائم!$A$2:$B$4,2,0),"") -> FIN | I160: =IF($H160="FIN","RTS",IF(ISNUMBER(SEARCH("مجمد",$E160)),"FRZ",IF(ISNUMBER(SEARCH("مبرد",$E160)),"CHL",IF(ISNUMBER(SEARCH("جاف",$E160)),"DRY",IF(ISNUMBER(SEARCH("استهلاك",$E160)),"CNS",IF(ISNUMBER(SEARCH("بيع",$E160)),"RTS","")))))) -> RTS | J160: =IF($H160="","",IF($N160=0,$Q160,SUMPRODUCT(($O$157:$O$590=$H160)*($P$157:$P$590=$I160)*$Q$157:$Q$590)+COUNTIFS($H$157:$H160,$H160,$I$157:$I160,$I160,$N$157:$N160,1))) -> 3 | M160: =IF($I160="","",COUNTIF($I$5:$I160,$I160)) -> 3 | N160: =IF($H160="","",IF(OR($H160<>$O160,$I160<>$P160),1,0)) -> 0 | O160: FIN | P160: RTS | Q160: 3 | R160: 260 | S160: 100 | T160: =IF(OR($R160="",$S160="",$S160=0),"",ROUND($R160/$S160,2)) -> 2.6
A161: 5 | B161: اضافات جبنة | C161: Cheese Add-on | D161: منتج نهائي | E161: جاهز للبيع | F161: =IF($H161="","",$H161&"-"&$I161&"-"&TEXT($J161,"000")) -> FIN-RTS-004 | G161: وحدة | H161: =IFERROR(VLOOKUP($D161,القوائم!$A$2:$B$4,2,0),"") -> FIN | I161: =IF($H161="FIN","RTS",IF(ISNUMBER(SEARCH("مجمد",$E161)),"FRZ",IF(ISNUMBER(SEARCH("مبرد",$E161)),"CHL",IF(ISNUMBER(SEARCH("جاف",$E161)),"DRY",IF(ISNUMBER(SEARCH("استهلاك",$E161)),"CNS",IF(ISNUMBER(SEARCH("بيع",$E161)),"RTS","")))))) -> RTS | J161: =IF($H161="","",IF($N161=0,$Q161,SUMPRODUCT(($O$157:$O$590=$H161)*($P$157:$P$590=$I161)*$Q$157:$Q$590)+COUNTIFS($H$157:$H161,$H161,$I$157:$I161,$I161,$N$157:$N161,1))) -> 4 | M161: =IF($I161="","",COUNTIF($I$5:$I161,$I161)) -> 4 | N161: =IF($H161="","",IF(OR($H161<>$O161,$I161<>$P161),1,0)) -> 0 | O161: FIN | P161: RTS | Q161: 4 | R161: 300 | S161: 100 | T161: =IF(OR($R161="",$S161="",$S161=0),"",ROUND($R161/$S161,2)) -> 3
A162: 6 | B162: الشوربة الايطالية | C162: Italian Soup | D162: منتج نهائي | E162: جاهز للبيع | F162: =IF($H162="","",$H162&"-"&$I162&"-"&TEXT($J162,"000")) -> FIN-RTS-005 | G162: وحدة | H162: =IFERROR(VLOOKUP($D162,القوائم!$A$2:$B$4,2,0),"") -> FIN | I162: =IF($H162="FIN","RTS",IF(ISNUMBER(SEARCH("مجمد",$E162)),"FRZ",IF(ISNUMBER(SEARCH("مبرد",$E162)),"CHL",IF(ISNUMBER(SEARCH("جاف",$E162)),"DRY",IF(ISNUMBER(SEARCH("استهلاك",$E162)),"CNS",IF(ISNUMBER(SEARCH("بيع",$E162)),"RTS","")))))) -> RTS | J162: =IF($H162="","",IF($N162=0,$Q162,SUMPRODUCT(($O$157:$O$590=$H162)*($P$157:$P$590=$I162)*$Q$157:$Q$590)+COUNTIFS($H$157:$H162,$H162,$I$157:$I162,$I162,$N$157:$N162,1))) -> 5 | M162: =IF($I162="","",COUNTIF($I$5:$I162,$I162)) -> 5 | N162: =IF($H162="","",IF(OR($H162<>$O162,$I162<>$P162),1,0)) -> 0 | O162: FIN | P162: RTS | Q162: 5 | R162: 60 | S162: 100 | T162: =IF(OR($R162="",$S162="",$S162=0),"",ROUND($R162/$S162,2)) -> 0.6
A163: 7 | B163: الشوربة السعودية | C163: Saudi Soup | D163: منتج نهائي | E163: جاهز للبيع | F163: =IF($H163="","",$H163&"-"&$I163&"-"&TEXT($J163,"000")) -> FIN-RTS-006 | G163: وحدة | H163: =IFERROR(VLOOKUP($D163,القوائم!$A$2:$B$4,2,0),"") -> FIN | I163: =IF($H163="FIN","RTS",IF(ISNUMBER(SEARCH("مجمد",$E163)),"FRZ",IF(ISNUMBER(SEARCH("مبرد",$E163)),"CHL",IF(ISNUMBER(SEARCH("جاف",$E163)),"DRY",IF(ISNUMBER(SEARCH("استهلاك",$E163)),"CNS",IF(ISNUMBER(SEARCH("بيع",$E163)),"RTS","")))))) -> RTS | J163: =IF($H163="","",IF($N163=0,$Q163,SUMPRODUCT(($O$157:$O$590=$H163)*($P$157:$P$590=$I163)*$Q$157:$Q$590)+COUNTIFS($H$157:$H163,$H163,$I$157:$I163,$I163,$N$157:$N163,1))) -> 6 | M163: =IF($I163="","",COUNTIF($I$5:$I163,$I163)) -> 6 | N163: =IF($H163="","",IF(OR($H163<>$O163,$I163<>$P163),1,0)) -> 0 | O163: FIN | P163: RTS | Q163: 6 | R163: 65 | S163: 100 | T163: =IF(OR($R163="",$S163="",$S163=0),"",ROUND($R163/$S163,2)) -> 0.65
A164: 8 | B164: الفريدو باستا خالي من الجلوتين | C164: Alfredo Pasta Gluten-Free | D164: منتج نهائي | E164: جاهز للبيع | F164: =IF($H164="","",$H164&"-"&$I164&"-"&TEXT($J164,"000")) -> FIN-RTS-007 | G164: وحدة | H164: =IFERROR(VLOOKUP($D164,القوائم!$A$2:$B$4,2,0),"") -> FIN | I164: =IF($H164="FIN","RTS",IF(ISNUMBER(SEARCH("مجمد",$E164)),"FRZ",IF(ISNUMBER(SEARCH("مبرد",$E164)),"CHL",IF(ISNUMBER(SEARCH("جاف",$E164)),"DRY",IF(ISNUMBER(SEARCH("استهلاك",$E164)),"CNS",IF(ISNUMBER(SEARCH("بيع",$E164)),"RTS","")))))) -> RTS | J164: =IF($H164="","",IF($N164=0,$Q164,SUMPRODUCT(($O$157:$O$590=$H164)*($P$157:$P$590=$I164)*$Q$157:$Q$590)+COUNTIFS($H$157:$H164,$H164,$I$157:$I164,$I164,$N$157:$N164,1))) -> 7 | M164: =IF($I164="","",COUNTIF($I$5:$I164,$I164)) -> 7 | N164: =IF($H164="","",IF(OR($H164<>$O164,$I164<>$P164),1,0)) -> 0 | O164: FIN | P164: RTS | Q164: 7 | R164: 200 | S164: 100 | T164: =IF(OR($R164="",$S164="",$S164=0),"",ROUND($R164/$S164,2)) -> 2
A165: 9 | B165: القسائم الشرائية والباقات | C165: Vouchers & Packages | D165: مواد خام | E165: استهلاكي | F165: =IF($H165="","",$H165&"-"&$I165&"-"&TEXT($J165,"000")) -> RAW-CNS-002 | G165: وحدة | H165: =IFERROR(VLOOKUP($D165,القوائم!$A$2:$B$4,2,0),"") -> RAW | I165: =IF($H165="FIN","RTS",IF(ISNUMBER(SEARCH("مجمد",$E165)),"FRZ",IF(ISNUMBER(SEARCH("مبرد",$E165)),"CHL",IF(ISNUMBER(SEARCH("جاف",$E165)),"DRY",IF(ISNUMBER(SEARCH("استهلاك",$E165)),"CNS",IF(ISNUMBER(SEARCH("بيع",$E165)),"RTS","")))))) -> CNS | J165: =IF($H165="","",IF($N165=0,$Q165,SUMPRODUCT(($O$157:$O$590=$H165)*($P$157:$P$590=$I165)*$Q$157:$Q$590)+COUNTIFS($H$157:$H165,$H165,$I$157:$I165,$I165,$N$157:$N165,1))) -> 2 | M165: =IF($I165="","",COUNTIF($I$5:$I165,$I165)) -> 3 | N165: =IF($H165="","",IF(OR($H165<>$O165,$I165<>$P165),1,0)) -> 0 | O165: RAW | P165: CNS | Q165: 2 | T165: =IF(OR($R165="",$S165="",$S165=0),"",ROUND($R165/$S165,2))
A166: 10 | B166: باركا الحلوم | C166: Borek Halloumi | D166: منتج نهائي | E166: جاهز للبيع | F166: =IF($H166="","",$H166&"-"&$I166&"-"&TEXT($J166,"000")) -> FIN-RTS-008 | G166: وحدة | H166: =IFERROR(VLOOKUP($D166,القوائم!$A$2:$B$4,2,0),"") -> FIN | I166: =IF($H166="FIN","RTS",IF(ISNUMBER(SEARCH("مجمد",$E166)),"FRZ",IF(ISNUMBER(SEARCH("مبرد",$E166)),"CHL",IF(ISNUMBER(SEARCH("جاف",$E166)),"DRY",IF(ISNUMBER(SEARCH("استهلاك",$E166)),"CNS",IF(ISNUMBER(SEARCH("بيع",$E166)),"RTS","")))))) -> RTS | J166: =IF($H166="","",IF($N166=0,$Q166,SUMPRODUCT(($O$157:$O$590=$H166)*($P$157:$P$590=$I166)*$Q$157:$Q$590)+COUNTIFS($H$157:$H166,$H166,$I$157:$I166,$I166,$N$157:$N166,1))) -> 8 | M166: =IF($I166="","",COUNTIF($I$5:$I166,$I166)) -> 8 | N166: =IF($H166="","",IF(OR($H166<>$O166,$I166<>$P166),1,0)) -> 0 | O166: FIN | P166: RTS | Q166: 8 | R166: 300 | S166: 100 | T166: =IF(OR($R166="",$S166="",$S166=0),"",ROUND($R166/$S166,2)) -> 3
A167: 11 | B167: باركا المسخن | C167: Borek Musakhan | D167: منتج نهائي | E167: جاهز للبيع | F167: =IF($H167="","",$H167&"-"&$I167&"-"&TEXT($J167,"000")) -> FIN-RTS-009 | G167: وحدة | H167: =IFERROR(VLOOKUP($D167,القوائم!$A$2:$B$4,2,0),"") -> FIN | I167: =IF($H167="FIN","RTS",IF(ISNUMBER(SEARCH("مجمد",$E167)),"FRZ",IF(ISNUMBER(SEARCH("مبرد",$E167)),"CHL",IF(ISNUMBER(SEARCH("جاف",$E167)),"DRY",IF(ISNUMBER(SEARCH("استهلاك",$E167)),"CNS",IF(ISNUMBER(SEARCH("بيع",$E167)),"RTS","")))))) -> RTS | J167: =IF($H167="","",IF($N167=0,$Q167,SUMPRODUCT(($O$157:$O$590=$H167)*($P$157:$P$590=$I167)*$Q$157:$Q$590)+COUNTIFS($H$157:$H167,$H167,$I$157:$I167,$I167,$N$157:$N167,1))) -> 9 | M167: =IF($I167="","",COUNTIF($I$5:$I167,$I167)) -> 9 | N167: =IF($H167="","",IF(OR($H167<>$O167,$I167<>$P167),1,0)) -> 0 | O167: FIN | P167: RTS | Q167: 9 | R167: 290 | S167: 100 | T167: =IF(OR($R167="",$S167="",$S167=0),"",ROUND($R167/$S167,2)) -> 2.9
A168: 12 | B168: باركا حلوم | C168: Borek Halloumi | D168: منتج نهائي | E168: جاهز للبيع | F168: =IF($H168="","",$H168&"-"&$I168&"-"&TEXT($J168,"000")) -> FIN-RTS-010 | G168: وحدة | H168: =IFERROR(VLOOKUP($D168,القوائم!$A$2:$B$4,2,0),"") -> FIN | I168: =IF($H168="FIN","RTS",IF(ISNUMBER(SEARCH("مجمد",$E168)),"FRZ",IF(ISNUMBER(SEARCH("مبرد",$E168)),"CHL",IF(ISNUMBER(SEARCH("جاف",$E168)),"DRY",IF(ISNUMBER(SEARCH("استهلاك",$E168)),"CNS",IF(ISNUMBER(SEARCH("بيع",$E168)),"RTS","")))))) -> RTS | J168: =IF($H168="","",IF($N168=0,$Q168,SUMPRODUCT(($O$157:$O$590=$H168)*($P$157:$P$590=$I168)*$Q$157:$Q$590)+COUNTIFS($H$157:$H168,$H168,$I$157:$I168,$I168,$N$157:$N168,1))) -> 10 | M168: =IF($I168="","",COUNTIF($I$5:$I168,$I168)) -> 10 | N168: =IF($H168="","",IF(OR($H168<>$O168,$I168<>$P168),1,0)) -> 0 | O168: FIN | P168: RTS | Q168: 10 | R168: 300 | S168: 100 | T168: =IF(OR($R168="",$S168="",$S168=0),"",ROUND($R168/$S168,2)) -> 3
A169: 13 | B169: باركا دجاج | C169: Borek Chicken | D169: منتج نهائي | E169: جاهز للبيع | F169: =IF($H169="","",$H169&"-"&$I169&"-"&TEXT($J169,"000")) -> FIN-RTS-011 | G169: وحدة | H169: =IFERROR(VLOOKUP($D169,القوائم!$A$2:$B$4,2,0),"") -> FIN | I169: =IF($H169="FIN","RTS",IF(ISNUMBER(SEARCH("مجمد",$E169)),"FRZ",IF(ISNUMBER(SEARCH("مبرد",$E169)),"CHL",IF(ISNUMBER(SEARCH("جاف",$E169)),"DRY",IF(ISNUMBER(SEARCH("استهلاك",$E169)),"CNS",IF(ISNUMBER(SEARCH("بيع",$E169)),"RTS","")))))) -> RTS | J169: =IF($H169="","",IF($N169=0,$Q169,SUMPRODUCT(($O$157:$O$590=$H169)*($P$157:$P$590=$I169)*$Q$157:$Q$590)+COUNTIFS($H$157:$H169,$H169,$I$157:$I169,$I169,$N$157:$N169,1))) -> 11 | M169: =IF($I169="","",COUNTIF($I$5:$I169,$I169)) -> 11 | N169: =IF($H169="","",IF(OR($H169<>$O169,$I169<>$P169),1,0)) -> 0 | O169: FIN | P169: RTS | Q169: 11 | R169: 280 | S169: 100 | T169: =IF(OR($R169="",$S169="",$S169=0),"",ROUND($R169/$S169,2)) -> 2.8
A170: 14 | B170: باركا مسخن | C170: Borek Musakhan | D170: منتج نهائي | E170: جاهز للبيع | F170: =IF($H170="","",$H170&"-"&$I170&"-"&TEXT($J170,"000")) -> FIN-RTS-012 | G170: وحدة | H170: =IFERROR(VLOOKUP($D170,القوائم!$A$2:$B$4,2,0),"") -> FIN | I170: =IF($H170="FIN","RTS",IF(ISNUMBER(SEARCH("مجمد",$E170)),"FRZ",IF(ISNUMBER(SEARCH("مبرد",$E170)),"CHL",IF(ISNUMBER(SEARCH("جاف",$E170)),"DRY",IF(ISNUMBER(SEARCH("استهلاك",$E170)),"CNS",IF(ISNUMBER(SEARCH("بيع",$E170)),"RTS","")))))) -> RTS | J170: =IF($H170="","",IF($N170=0,$Q170,SUMPRODUCT(($O$157:$O$590=$H170)*($P$157:$P$590=$I170)*$Q$157:$Q$590)+COUNTIFS($H$157:$H170,$H170,$I$157:$I170,$I170,$N$157:$N170,1))) -> 12 | M170: =IF($I170="","",COUNTIF($I$5:$I170,$I170)) -> 12 | N170: =IF($H170="","",IF(OR($H170<>$O170,$I170<>$P170),1,0)) -> 0 | O170: FIN | P170: RTS | Q170: 12 | R170: 290 | S170: 100 | T170: =IF(OR($R170="",$S170="",$S170=0),"",ROUND($R170/$S170,2)) -> 2.9
A171: 15 | B171: باستا الفريدو | C171: Alfredo Pasta | D171: منتج نهائي | E171: جاهز للبيع | F171: =IF($H171="","",$H171&"-"&$I171&"-"&TEXT($J171,"000")) -> FIN-RTS-013 | G171: وحدة | H171: =IFERROR(VLOOKUP($D171,القوائم!$A$2:$B$4,2,0),"") -> FIN | I171: =IF($H171="FIN","RTS",IF(ISNUMBER(SEARCH("مجمد",$E171)),"FRZ",IF(ISNUMBER(SEARCH("مبرد",$E171)),"CHL",IF(ISNUMBER(SEARCH("جاف",$E171)),"DRY",IF(ISNUMBER(SEARCH("استهلاك",$E171)),"CNS",IF(ISNUMBER(SEARCH("بيع",$E171)),"RTS","")))))) -> RTS | J171: =IF($H171="","",IF($N171=0,$Q171,SUMPRODUCT(($O$157:$O$590=$H171)*($P$157:$P$590=$I171)*$Q$157:$Q$590)+COUNTIFS($H$157:$H171,$H171,$I$157:$I171,$I171,$N$157:$N171,1))) -> 13 | M171: =IF($I171="","",COUNTIF($I$5:$I171,$I171)) -> 13 | N171: =IF($H171="","",IF(OR($H171<>$O171,$I171<>$P171),1,0)) -> 0 | O171: FIN | P171: RTS | Q171: 13 | R171: 200 | S171: 100 | T171: =IF(OR($R171="",$S171="",$S171=0),"",ROUND($R171/$S171,2)) -> 2
A172: 16 | B172: باستا بيستو | C172: Pesto Pasta | D172: منتج نهائي | E172: جاهز للبيع | F172: =IF($H172="","",$H172&"-"&$I172&"-"&TEXT($J172,"000")) -> FIN-RTS-014 | G172: وحدة | H172: =IFERROR(VLOOKUP($D172,القوائم!$A$2:$B$4,2,0),"") -> FIN | I172: =IF($H172="FIN","RTS",IF(ISNUMBER(SEARCH("مجمد",$E172)),"FRZ",IF(ISNUMBER(SEARCH("مبرد",$E172)),"CHL",IF(ISNUMBER(SEARCH("جاف",$E172)),"DRY",IF(ISNUMBER(SEARCH("استهلاك",$E172)),"CNS",IF(ISNUMBER(SEARCH("بيع",$E172)),"RTS","")))))) -> RTS | J172: =IF($H172="","",IF($N172=0,$Q172,SUMPRODUCT(($O$157:$O$590=$H172)*($P$157:$P$590=$I172)*$Q$157:$Q$590)+COUNTIFS($H$157:$H172,$H172,$I$157:$I172,$I172,$N$157:$N172,1))) -> 14 | M172: =IF($I172="","",COUNTIF($I$5:$I172,$I172)) -> 14 | N172: =IF($H172="","",IF(OR($H172<>$O172,$I172<>$P172),1,0)) -> 0 | O172: FIN | P172: RTS | Q172: 14 | R172: 250 | S172: 100 | T172: =IF(OR($R172="",$S172="",$S172=0),"",ROUND($R172/$S172,2)) -> 2.5
A173: 17 | B173: باستا بيستو خالي من الجلوتين | C173: Pesto Gluten-Free Pasta | D173: منتج نهائي | E173: جاهز للبيع | F173: =IF($H173="","",$H173&"-"&$I173&"-"&TEXT($J173,"000")) -> FIN-RTS-015 | G173: وحدة | H173: =IFERROR(VLOOKUP($D173,القوائم!$A$2:$B$4,2,0),"") -> FIN | I173: =IF($H173="FIN","RTS",IF(ISNUMBER(SEARCH("مجمد",$E173)),"FRZ",IF(ISNUMBER(SEARCH("مبرد",$E173)),"CHL",IF(ISNUMBER(SEARCH("جاف",$E173)),"DRY",IF(ISNUMBER(SEARCH("استهلاك",$E173)),"CNS",IF(ISNUMBER(SEARCH("بيع",$E173)),"RTS","")))))) -> RTS | J173: =IF($H173="","",IF($N173=0,$Q173,SUMPRODUCT(($O$157:$O$590=$H173)*($P$157:$P$590=$I173)*$Q$157:$Q$590)+COUNTIFS($H$157:$H173,$H173,$I$157:$I173,$I173,$N$157:$N173,1))) -> 15 | M173: =IF($I173="","",COUNTIF($I$5:$I173,$I173)) -> 15 | N173: =IF($H173="","",IF(OR($H173<>$O173,$I173<>$P173),1,0)) -> 0 | O173: FIN | P173: RTS | Q173: 15 | R173: 250 | S173: 100 | T173: =IF(OR($R173="",$S173="",$S173=0),"",ROUND($R173/$S173,2)) -> 2.5
A174: 18 | B174: باستا بيني روزيه | C174: Penne Rose Pasta | D174: منتج نهائي | E174: جاهز للبيع | F174: =IF($H174="","",$H174&"-"&$I174&"-"&TEXT($J174,"000")) -> FIN-RTS-016 | G174: وحدة | H174: =IFERROR(VLOOKUP($D174,القوائم!$A$2:$B$4,2,0),"") -> FIN | I174: =IF($H174="FIN","RTS",IF(ISNUMBER(SEARCH("مجمد",$E174)),"FRZ",IF(ISNUMBER(SEARCH("مبرد",$E174)),"CHL",IF(ISNUMBER(SEARCH("جاف",$E174)),"DRY",IF(ISNUMBER(SEARCH("استهلاك",$E174)),"CNS",IF(ISNUMBER(SEARCH("بيع",$E174)),"RTS","")))))) -> RTS | J174: =IF($H174="","",IF($N174=0,$Q174,SUMPRODUCT(($O$157:$O$590=$H174)*($P$157:$P$590=$I174)*$Q$157:$Q$590)+COUNTIFS($H$157:$H174,$H174,$I$157:$I174,$I174,$N$157:$N174,1))) -> 16 | M174: =IF($I174="","",COUNTIF($I$5:$I174,$I174)) -> 16 | N174: =IF($H174="","",IF(OR($H174<>$O174,$I174<>$P174),1,0)) -> 0 | O174: FIN | P174: RTS | Q174: 16 | R174: 175 | S174: 100 | T174: =IF(OR($R174="",$S174="",$S174=0),"",ROUND($R174/$S174,2)) -> 1.75
...

Sheet جرد المجمّدة
A1: جرد المنتجات المجمّدة — تخزين مجمد
A2: تاريخ الجرد: __________ القائم بالجرد: __________ (تتحدّث تلقائيًا من السجل) | F2: ="عدد الأصناف: "&COUNTIF('إدخال وسجل المنتجات'!$I$5:$I$590,"FRZ") -> عدد الأصناف: 17
A3: م | B3: الكود | C3: اسم المنتج | D3: الاسم EN | E3: الفئة | F3: الوحدة | G3: الكمية الفعلية | H3: ملاحظات | J3: إجمالي الوزن (كجم)
A4: =IF($I4=0,"",1) -> 1 | B4: =IF($I4=0,"",INDEX('إدخال وسجل المنتجات'!$F$5:$F$590,$I4)) -> RAW-FRZ-001 | C4: =IF($I4=0,"",INDEX('إدخال وسجل المنتجات'!$B$5:$B$590,$I4)) -> كاس ثلج | D4: =IF($I4=0,"",INDEX('إدخال وسجل المنتجات'!$C$5:$C$590,$I4)) -> Cup Of Ice | E4: =IF($I4=0,"",INDEX('إدخال وسجل المنتجات'!$D$5:$D$590,$I4)) -> مواد خام | F4: =IF($I4=0,"",INDEX('إدخال وسجل المنتجات'!$G$5:$G$590,$I4)) -> وحدة | I4: =SUMPRODUCT(('إدخال وسجل المنتجات'!$I$5:$I$590="FRZ")*('إدخال وسجل المنتجات'!$M$5:$M$590=1)*(ROW('إدخال وسجل المنتجات'!$I$5:$I$590)-4)) -> 249 | J4: =IF($I4=0,"",IF($G4="","",$G4*IF(INDEX('إدخال وسجل المنتجات'!$U$5:$U$590,$I4)=0,1,INDEX('إدخال وسجل المنتجات'!$U$5:$U$590,$I4))))
A5: =IF($I5=0,"",2) -> 2 | B5: =IF($I5=0,"",INDEX('إدخال وسجل المنتجات'!$F$5:$F$590,$I5)) -> RAW-FRZ-002 | C5: =IF($I5=0,"",INDEX('إدخال وسجل المنتجات'!$B$5:$B$590,$I5)) -> ببروني | D5: =IF($I5=0,"",INDEX('إدخال وسجل المنتجات'!$C$5:$C$590,$I5)) -> Pepperoni | E5: =IF($I5=0,"",INDEX('إدخال وسجل المنتجات'!$D$5:$D$590,$I5)) -> مواد خام | F5: =IF($I5=0,"",INDEX('إدخال وسجل المنتجات'!$G$5:$G$590,$I5)) -> كيلو | I5: =SUMPRODUCT(('إدخال وسجل المنتجات'!$I$5:$I$590="FRZ")*('إدخال وسجل المنتجات'!$M$5:$M$590=2)*(ROW('إدخال وسجل المنتجات'!$I$5:$I$590)-4)) -> 284 | J5: =IF($I5=0,"",IF($G5="","",$G5*IF(INDEX('إدخال وسجل المنتجات'!$U$5:$U$590,$I5)=0,1,INDEX('إدخال وسجل المنتجات'!$U$5:$U$590,$I5))))
A6: =IF($I6=0,"",3) -> 3 | B6: =IF($I6=0,"",INDEX('إدخال وسجل المنتجات'!$F$5:$F$590,$I6)) -> RAW-FRZ-003 | C6: =IF($I6=0,"",INDEX('إدخال وسجل المنتجات'!$B$5:$B$590,$I6)) -> ثلج | D6: =IF($I6=0,"",INDEX('إدخال وسجل المنتجات'!$C$5:$C$590,$I6)) -> Ice | E6: =IF($I6=0,"",INDEX('إدخال وسجل المنتجات'!$D$5:$D$590,$I6)) -> مواد خام | F6: =IF($I6=0,"",INDEX('إدخال وسجل المنتجات'!$G$5:$G$590,$I6)) -> كيلو | I6: =SUMPRODUCT(('إدخال وسجل المنتجات'!$I$5:$I$590="FRZ")*('إدخال وسجل المنتجات'!$M$5:$M$590=3)*(ROW('إدخال وسجل المنتجات'!$I$5:$I$590)-4)) -> 323 | J6: =IF($I6=0,"",IF($G6="","",$G6*IF(INDEX('إدخال وسجل المنتجات'!$U$5:$U$590,$I6)=0,1,INDEX('إدخال وسجل المنتجات'!$U$5:$U$590,$I6))))
A7: =IF($I7=0,"",4) -> 4 | B7: =IF($I7=0,"",INDEX('إدخال وسجل المنتجات'!$F$5:$F$590,$I7)) -> RAW-FRZ-004 | C7: =IF($I7=0,"",INDEX('إدخال وسجل المنتجات'!$B$5:$B$590,$I7)) -> جمبري | D7: =IF($I7=0,"",INDEX('إدخال وسجل المنتجات'!$C$5:$C$590,$I7)) -> Shrimp | E7: =IF($I7=0,"",INDEX('إدخال وسجل المنتجات'!$D$5:$D$590,$I7)) -> مواد خام | F7: =IF($I7=0,"",INDEX('إدخال وسجل المنتجات'!$G$5:$G$590,$I7)) -> كيلو | I7: =SUMPRODUCT(('إدخال وسجل المنتجات'!$I$5:$I$590="FRZ")*('إدخال وسجل المنتجات'!$M$5:$M$590=4)*(ROW('إدخال وسجل المنتجات'!$I$5:$I$590)-4)) -> 338 | J7: =IF($I7=0,"",IF($G7="","",$G7*IF(INDEX('إدخال وسجل المنتجات'!$U$5:$U$590,$I7)=0,1,INDEX('إدخال وسجل المنتجات'!$U$5:$U$590,$I7))))
A8: =IF($I8=0,"",5) -> 5 | B8: =IF($I8=0,"",INDEX('إدخال وسجل المنتجات'!$F$5:$F$590,$I8)) -> RAW-FRZ-005 | C8: =IF($I8=0,"",INDEX('إدخال وسجل المنتجات'!$B$5:$B$590,$I8)) -> سلامي | D8: =IF($I8=0,"",INDEX('إدخال وسجل المنتجات'!$C$5:$C$590,$I8)) -> Salami | E8: =IF($I8=0,"",INDEX('إدخال وسجل المنتجات'!$D$5:$D$590,$I8)) -> مواد خام | F8: =IF($I8=0,"",INDEX('إدخال وسجل المنتجات'!$G$5:$G$590,$I8)) -> كيلو | I8: =SUMPRODUCT(('إدخال وسجل المنتجات'!$I$5:$I$590="FRZ")*('إدخال وسجل المنتجات'!$M$5:$M$590=5)*(ROW('إدخال وسجل المنتجات'!$I$5:$I$590)-4)) -> 407 | J8: =IF($I8=0,"",IF($G8="","",$G8*IF(INDEX('إدخال وسجل المنتجات'!$U$5:$U$590,$I8)=0,1,INDEX('إدخال وسجل المنتجات'!$U$5:$U$590,$I8))))
A9: =IF($I9=0,"",6) -> 6 | B9: =IF($I9=0,"",INDEX('إدخال وسجل المنتجات'!$F$5:$F$590,$I9)) -> RAW-FRZ-006 | C9: =IF($I9=0,"",INDEX('إدخال وسجل المنتجات'!$B$5:$B$590,$I9)) -> شرائح لحم امريكي | D9: =IF($I9=0,"",INDEX('إدخال وسجل المنتجات'!$C$5:$C$590,$I9)) -> Sliced Meat | E9: =IF($I9=0,"",INDEX('إدخال وسجل المنتجات'!$D$5:$D$590,$I9)) -> مواد خام | F9: =IF($I9=0,"",INDEX('إدخال وسجل المنتجات'!$G$5:$G$590,$I9)) -> كيلو | I9: =SUMPRODUCT(('إدخال وسجل المنتجات'!$I$5:$I$590="FRZ")*('إدخال وسجل المنتجات'!$M$5:$M$590=6)*(ROW('إدخال وسجل المنتجات'!$I$5:$I$590)-4)) -> 421 | J9: =IF($I9=0,"",IF($G9="","",$G9*IF(INDEX('إدخال وسجل المنتجات'!$U$5:$U$590,$I9)=0,1,INDEX('إدخال وسجل المنتجات'!$U$5:$U$590,$I9))))
A10: =IF($I10=0,"",7) -> 7 | B10: =IF($I10=0,"",INDEX('إدخال وسجل المنتجات'!$F$5:$F$590,$I10)) -> RAW-FRZ-007 | C10: =IF($I10=0,"",INDEX('إدخال وسجل المنتجات'!$B$5:$B$590,$I10)) -> شرائح لحم بقري | D10: =IF($I10=0,"",INDEX('إدخال وسجل المنتجات'!$C$5:$C$590,$I10)) -> Sliced Meat | E10: =IF($I10=0,"",INDEX('إدخال وسجل المنتجات'!$D$5:$D$590,$I10)) -> مواد خام | F10: =IF($I10=0,"",INDEX('إدخال وسجل المنتجات'!$G$5:$G$590,$I10)) -> كيلو | I10: =SUMPRODUCT(('إدخال وسجل المنتجات'!$I$5:$I$590="FRZ")*('إدخال وسجل المنتجات'!$M$5:$M$590=7)*(ROW('إدخال وسجل المنتجات'!$I$5:$I$590)-4)) -> 422 | J10: =IF($I10=0,"",IF($G10="","",$G10*IF(INDEX('إدخال وسجل المنتجات'!$U$5:$U$590,$I10)=0,1,INDEX('إدخال وسجل المنتجات'!$U$5:$U$590,$I10))))
A11: =IF($I11=0,"",8) -> 8 | B11: =IF($I11=0,"",INDEX('إدخال وسجل المنتجات'!$F$5:$F$590,$I11)) -> TRN-FRZ-001 | C11: =IF($I11=0,"",INDEX('إدخال وسجل المنتجات'!$B$5:$B$590,$I11)) -> صدور الدجاج المتبلة | D11: =IF($I11=0,"",INDEX('إدخال وسجل المنتجات'!$C$5:$C$590,$I11)) -> Marinated Chicken Breast | E11: =IF($I11=0,"",INDEX('إدخال وسجل المنتجات'!$D$5:$D$590,$I11)) -> مواد تحويلية | F11: =IF($I11=0,"",INDEX('إدخال وسجل المنتجات'!$G$5:$G$590,$I11)) -> كيلو | I11: =SUMPRODUCT(('إدخال وسجل المنتجات'!$I$5:$I$590="FRZ")*('إدخال وسجل المنتجات'!$M$5:$M$590=8)*(ROW('إدخال وسجل المنتجات'!$I$5:$I$590)-4)) -> 436 | J11: =IF($I11=0,"",IF($G11="","",$G11*IF(INDEX('إدخال وسجل المنتجات'!$U$5:$U$590,$I11)=0,1,INDEX('إدخال وسجل المنتجات'!$U$5:$U$590,$I11))))
A12: =IF($I12=0,"",9) -> 9 | B12: =IF($I12=0,"",INDEX('إدخال وسجل المنتجات'!$F$5:$F$590,$I12)) -> RAW-FRZ-008 | C12: =IF($I12=0,"",INDEX('إدخال وسجل المنتجات'!$B$5:$B$590,$I12)) -> صدور دجاج | D12: =IF($I12=0,"",INDEX('إدخال وسجل المنتجات'!$C$5:$C$590,$I12)) -> Chicken Breast | E12: =IF($I12=0,"",INDEX('إدخال وسجل المنتجات'!$D$5:$D$590,$I12)) -> مواد خام | F12: =IF($I12=0,"",INDEX('إدخال وسجل المنتجات'!$G$5:$G$590,$I12)) -> كيلو | I12: =SUMPRODUCT(('إدخال وسجل المنتجات'!$I$5:$I$590="FRZ")*('إدخال وسجل المنتجات'!$M$5:$M$590=9)*(ROW('إدخال وسجل المنتجات'!$I$5:$I$590)-4)) -> 437 | J12: =IF($I12=0,"",IF($G12="","",$G12*IF(INDEX('إدخال وسجل المنتجات'!$U$5:$U$590,$I12)=0,1,INDEX('إدخال وسجل المنتجات'!$U$5:$U$590,$I12))))
A13: =IF($I13=0,"",10) -> 10 | B13: =IF($I13=0,"",INDEX('إدخال وسجل المنتجات'!$F$5:$F$590,$I13)) -> RAW-FRZ-009 | C13: =IF($I13=0,"",INDEX('إدخال وسجل المنتجات'!$B$5:$B$590,$I13)) -> لحم البريسكت | D13: =IF($I13=0,"",INDEX('إدخال وسجل المنتجات'!$C$5:$C$590,$I13)) -> Meat Brisket | E13: =IF($I13=0,"",INDEX('إدخال وسجل المنتجات'!$D$5:$D$590,$I13)) -> مواد خام | F13: =IF($I13=0,"",INDEX('إدخال وسجل المنتجات'!$G$5:$G$590,$I13)) -> كيلو | I13: =SUMPRODUCT(('إدخال وسجل المنتجات'!$I$5:$I$590="FRZ")*('إدخال وسجل المنتجات'!$M$5:$M$590=10)*(ROW('إدخال وسجل المنتجات'!$I$5:$I$590)-4)) -> 534 | J13: =IF($I13=0,"",IF($G13="","",$G13*IF(INDEX('إدخال وسجل المنتجات'!$U$5:$U$590,$I13)=0,1,INDEX('إدخال وسجل المنتجات'!$U$5:$U$590,$I13))))
A14: =IF($I14=0,"",11) -> 11 | B14: =IF($I14=0,"",INDEX('إدخال وسجل المنتجات'!$F$5:$F$590,$I14)) -> RAW-FRZ-010 | C14: =IF($I14=0,"",INDEX('إدخال وسجل المنتجات'!$B$5:$B$590,$I14)) -> لحم بريسكت | D14: =IF($I14=0,"",INDEX('إدخال وسجل المنتجات'!$C$5:$C$590,$I14)) -> Meat Brisket | E14: =IF($I14=0,"",INDEX('إدخال وسجل المنتجات'!$D$5:$D$590,$I14)) -> مواد خام | F14: =IF($I14=0,"",INDEX('إدخال وسجل المنتجات'!$G$5:$G$590,$I14)) -> كيلو | I14: =SUMPRODUCT(('إدخال وسجل المنتجات'!$I$5:$I$590="FRZ")*('إدخال وسجل المنتجات'!$M$5:$M$590=11)*(ROW('إدخال وسجل المنتجات'!$I$5:$I$590)-4)) -> 535 | J14: =IF($I14=0,"",IF($G14="","",$G14*IF(INDEX('إدخال وسجل المنتجات'!$U$5:$U$590,$I14)=0,1,INDEX('إدخال وسجل المنتجات'!$U$5:$U$590,$I14))))
A15: =IF($I15=0,"",12) -> 12 | B15: =IF($I15=0,"",INDEX('إدخال وسجل المنتجات'!$F$5:$F$590,$I15)) -> RAW-FRZ-011 | C15: =IF($I15=0,"",INDEX('إدخال وسجل المنتجات'!$B$5:$B$590,$I15)) -> لحم بيبروني بلاك انجوس | D15: =IF($I15=0,"",INDEX('إدخال وسجل المنتجات'!$C$5:$C$590,$I15)) -> Meat Pepperoni Black Angus | E15: =IF($I15=0,"",INDEX('إدخال وسجل المنتجات'!$D$5:$D$590,$I15)) -> مواد خام | F15: =IF($I15=0,"",INDEX('إدخال وسجل المنتجات'!$G$5:$G$590,$I15)) -> كيلو | I15: =SUMPRODUCT(('إدخال وسجل المنتجات'!$I$5:$I$590="FRZ")*('إدخال وسجل المنتجات'!$M$5:$M$590=12)*(ROW('إدخال وسجل المنتجات'!$I$5:$I$590)-4)) -> 536 | J15: =IF($I15=0,"",IF($G15="","",$G15*IF(INDEX('إدخال وسجل المنتجات'!$U$5:$U$590,$I15)=0,1,INDEX('إدخال وسجل المنتجات'!$U$5:$U$590,$I15))))
A16: =IF($I16=0,"",13) -> 13 | B16: =IF($I16=0,"",INDEX('إدخال وسجل المنتجات'!$F$5:$F$590,$I16)) -> RAW-FRZ-012 | C16: =IF($I16=0,"",INDEX('إدخال وسجل المنتجات'!$B$5:$B$590,$I16)) -> لحم غنم | D16: =IF($I16=0,"",INDEX('إدخال وسجل المنتجات'!$C$5:$C$590,$I16)) -> Meat Lamb | E16: =IF($I16=0,"",INDEX('إدخال وسجل المنتجات'!$D$5:$D$590,$I16)) -> مواد خام | F16: =IF($I16=0,"",INDEX('إدخال وسجل المنتجات'!$G$5:$G$590,$I16)) -> كيلو | I16: =SUMPRODUCT(('إدخال وسجل المنتجات'!$I$5:$I$590="FRZ")*('إدخال وسجل المنتجات'!$M$5:$M$590=13)*(ROW('إدخال وسجل المنتجات'!$I$5:$I$590)-4)) -> 537 | J16: =IF($I16=0,"",IF($G16="","",$G16*IF(INDEX('إدخال وسجل المنتجات'!$U$5:$U$590,$I16)=0,1,INDEX('إدخال وسجل المنتجات'!$U$5:$U$590,$I16))))
A17: =IF($I17=0,"",14) -> 14 | B17: =IF($I17=0,"",INDEX('إدخال وسجل المنتجات'!$F$5:$F$590,$I17)) -> RAW-FRZ-013 | C17: =IF($I17=0,"",INDEX('إدخال وسجل المنتجات'!$B$5:$B$590,$I17)) -> لحم لازانيا مفروم | D17: =IF($I17=0,"",INDEX('إدخال وسجل المنتجات'!$C$5:$C$590,$I17)) -> Lasagna Ground Meat | E17: =IF($I17=0,"",INDEX('إدخال وسجل المنتجات'!$D$5:$D$590,$I17)) -> مواد خام | F17: =IF($I17=0,"",INDEX('إدخال وسجل المنتجات'!$G$5:$G$590,$I17)) -> كيلو | I17: =SUMPRODUCT(('إدخال وسجل المنتجات'!$I$5:$I$590="FRZ")*('إدخال وسجل المنتجات'!$M$5:$M$590=14)*(ROW('إدخال وسجل المنتجات'!$I$5:$I$590)-4)) -> 538 | J17: =IF($I17=0,"",IF($G17="","",$G17*IF(INDEX('إدخال وسجل المنتجات'!$U$5:$U$590,$I17)=0,1,INDEX('إدخال وسجل المنتجات'!$U$5:$U$590,$I17))))
A18: =IF($I18=0,"",15) -> 15 | B18: =IF($I18=0,"",INDEX('إدخال وسجل المنتجات'!$F$5:$F$590,$I18)) -> TRN-FRZ-002 | C18: =IF($I18=0,"",INDEX('إدخال وسجل المنتجات'!$B$5:$B$590,$I18)) -> لحم متبل | D18: =IF($I18=0,"",INDEX('إدخال وسجل المنتجات'!$C$5:$C$590,$I18)) -> Marinated Meat | E18: =IF($I18=0,"",INDEX('إدخال وسجل المنتجات'!$D$5:$D$590,$I18)) -> مواد تحويلية | F18: =IF($I18=0,"",INDEX('إدخال وسجل المنتجات'!$G$5:$G$590,$I18)) -> كيلو | I18: =SUMPRODUCT(('إدخال وسجل المنتجات'!$I$5:$I$590="FRZ")*('إدخال وسجل المنتجات'!$M$5:$M$590=15)*(ROW('إدخال وسجل المنتجات'!$I$5:$I$590)-4)) -> 539 | J18: =IF($I18=0,"",IF($G18="","",$G18*IF(INDEX('إدخال وسجل المنتجات'!$U$5:$U$590,$I18)=0,1,INDEX('إدخال وسجل المنتجات'!$U$5:$U$590,$I18))))
A19: =IF($I19=0,"",16) -> 16 | B19: =IF($I19=0,"",INDEX('إدخال وسجل المنتجات'!$F$5:$F$590,$I19)) -> RAW-FRZ-014 | C19: =IF($I19=0,"",INDEX('إدخال وسجل المنتجات'!$B$5:$B$590,$I19)) -> لحم مفروم | D19: =IF($I19=0,"",INDEX('إدخال وسجل المنتجات'!$C$5:$C$590,$I19)) -> Ground Meat | E19: =IF($I19=0,"",INDEX('إدخال وسجل المنتجات'!$D$5:$D$590,$I19)) -> مواد خام | F19: =IF($I19=0,"",INDEX('إدخال وسجل المنتجات'!$G$5:$G$590,$I19)) -> كيلو | I19: =SUMPRODUCT(('إدخال وسجل المنتجات'!$I$5:$I$590="FRZ")*('إدخال وسجل المنتجات'!$M$5:$M$590=16)*(ROW('إدخال وسجل المنتجات'!$I$5:$I$590)-4)) -> 540 | J19: =IF($I19=0,"",IF($G19="","",$G19*IF(INDEX('إدخال وسجل المنتجات'!$U$5:$U$590,$I19)=0,1,INDEX('إدخال وسجل المنتجات'!$U$5:$U$590,$I19))))
A20: =IF($I20=0,"",17) -> 17 | B20: =IF($I20=0,"",INDEX('إدخال وسجل المنتجات'!$F$5:$F$590,$I20)) -> RAW-FRZ-015 | C20: =IF($I20=0,"",INDEX('إدخال وسجل المنتجات'!$B$5:$B$590,$I20)) -> محار | D20: =IF($I20=0,"",INDEX('إدخال وسجل المنتجات'!$C$5:$C$590,$I20)) -> Clams | E20: =IF($I20=0,"",INDEX('إدخال وسجل المنتجات'!$D$5:$D$590,$I20)) -> مواد خام | F20: =IF($I20=0,"",INDEX('إدخال وسجل المنتجات'!$G$5:$G$590,$I20)) -> كيلو | I20: =SUMPRODUCT(('إدخال وسجل المنتجات'!$I$5:$I$590="FRZ")*('إدخال وسجل المنتجات'!$M$5:$M$590=17)*(ROW('إدخال وسجل المنتجات'!$I$5:$I$590)-4)) -> 549 | J20: =IF($I20=0,"",IF($G20="","",$G20*IF(INDEX('إدخال وسجل المنتجات'!$U$5:$U$590,$I20)=0,1,INDEX('إدخال وسجل المنتجات'!$U$5:$U$590,$I20))))
A21: =IF($I21=0,"",18) | B21: =IF($I21=0,"",INDEX('إدخال وسجل المنتجات'!$F$5:$F$590,$I21)) | C21: =IF($I21=0,"",INDEX('إدخال وسجل المنتجات'!$B$5:$B$590,$I21)) | D21: =IF($I21=0,"",INDEX('إدخال وسجل المنتجات'!$C$5:$C$590,$I21)) | E21: =IF($I21=0,"",INDEX('إدخال وسجل المنتجات'!$D$5:$D$590,$I21)) | F21: =IF($I21=0,"",INDEX('إدخال وسجل المنتجات'!$G$5:$G$590,$I21)) | I21: =SUMPRODUCT(('إدخال وسجل المنتجات'!$I$5:$I$590="FRZ")*('إدخال وسجل المنتجات'!$M$5:$M$590=18)*(ROW('إدخال وسجل المنتجات'!$I$5:$I$590)-4)) -> 0 | J21: =IF($I21=0,"",IF($G21="","",$G21*IF(INDEX('إدخال وسجل المنتجات'!$U$5:$U$590,$I21)=0,1,INDEX('إدخال وسجل المنتجات'!$U$5:$U$590,$I21))))
A22: =IF($I22=0,"",19) | B22: =IF($I22=0,"",INDEX('إدخال وسجل المنتجات'!$F$5:$F$590,$I22)) | C22: =IF($I22=0,"",INDEX('إدخال وسجل المنتجات'!$B$5:$B$590,$I22)) | D22: =IF($I22=0,"",INDEX('إدخال وسجل المنتجات'!$C$5:$C$590,$I22)) | E22: =IF($I22=0,"",INDEX('إدخال وسجل المنتجات'!$D$5:$D$590,$I22)) | F22: =IF($I22=0,"",INDEX('إدخال وسجل المنتجات'!$G$5:$G$590,$I22)) | I22: =SUMPRODUCT(('إدخال وسجل المنتجات'!$I$5:$I$590="FRZ")*('إدخال وسجل المنتجات'!$M$5:$M$590=19)*(ROW('إدخال وسجل المنتجات'!$I$5:$I$590)-4)) -> 0 | J22: =IF($I22=0,"",IF($G22="","",$G22*IF(INDEX('إدخال وسجل المنتجات'!$U$5:$U$590,$I22)=0,1,INDEX('إدخال وسجل المنتجات'!$U$5:$U$590,$I22))))
A23: =IF($I23=0,"",20) | B23: =IF($I23=0,"",INDEX('إدخال وسجل المنتجات'!$F$5:$F$590,$I23)) | C23: =IF($I23=0,"",INDEX('إدخال وسجل المنتجات'!$B$5:$B$590,$I23)) | D23: =IF($I23=0,"",INDEX('إدخال وسجل المنتجات'!$C$5:$C$590,$I23)) | E23: =IF($I23=0,"",INDEX('إدخال وسجل المنتجات'!$D$5:$D$590,$I23)) | F23: =IF($I23=0,"",INDEX('إدخال وسجل المنتجات'!$G$5:$G$590,$I23)) | I23: =SUMPRODUCT(('إدخال وسجل المنتجات'!$I$5:$I$590="FRZ")*('إدخال وسجل المنتجات'!$M$5:$M$590=20)*(ROW('إدخال وسجل المنتجات'!$I$5:$I$590)-4)) -> 0 | J23: =IF($I23=0,"",IF($G23="","",$G23*IF(INDEX('إدخال وسجل المنتجات'!$U$5:$U$590,$I23)=0,1,INDEX('إدخال وسجل المنتجات'!$U$5:$U$590,$I23))))
A24: =IF($I24=0,"",21) | B24: =IF($I24=0,"",INDEX('إدخال وسجل المنتجات'!$F$5:$F$590,$I24)) | C24: =IF($I24=0,"",INDEX('إدخال وسجل المنتجات'!$B$5:$B$590,$I24)) | D24: =IF($I24=0,"",INDEX('إدخال وسجل المنتجات'!$C$5:$C$590,$I24)) | E24: =IF($I24=0,"",INDEX('إدخال وسجل المنتجات'!$D$5:$D$590,$I24)) | F24: =IF($I24=0,"",INDEX('إدخال وسجل المنتجات'!$G$5:$G$590,$I24)) | I24: =SUMPRODUCT(('إدخال وسجل المنتجات'!$I$5:$I$590="FRZ")*('إدخال وسجل المنتجات'!$M$5:$M$590=21)*(ROW('إدخال وسجل المنتجات'!$I$5:$I$590)-4)) -> 0 | J24: =IF($I24=0,"",IF($G24="","",$G24*IF(INDEX('إدخال وسجل المنتجات'!$U$5:$U$590,$I24)=0,1,INDEX('إدخال وسجل المنتجات'!$U$5:$U$590,$I24))))
A25: =IF($I25=0,"",22) | B25: =IF($I25=0,"",INDEX('إدخال وسجل المنتجات'!$F$5:$F$590,$I25)) | C25: =IF($I25=0,"",INDEX('إدخال وسجل المنتجات'!$B$5:$B$590,$I25)) | D25: =IF($I25=0,"",INDEX('إدخال وسجل المنتجات'!$C$5:$C$590,$I25)) | E25: =IF($I25=0,"",INDEX('إدخال وسجل المنتجات'!$D$5:$D$590,$I25)) | F25: =IF($I25=0,"",INDEX('إدخال وسجل المنتجات'!$G$5:$G$590,$I25)) | I25: =SUMPRODUCT(('إدخال وسجل المنتجات'!$I$5:$I$590="FRZ")*('إدخال وسجل المنتجات'!$M$5:$M$590=22)*(ROW('إدخال وسجل المنتجات'!$I$5:$I$590)-4)) -> 0 | J25: =IF($I25=0,"",IF($G25="","",$G25*IF(INDEX('إدخال وسجل المنتجات'!$U$5:$U$590,$I25)=0,1,INDEX('إدخال وسجل المنتجات'!$U$5:$U$590,$I25))))
A26: =IF($I26=0,"",23) | B26: =IF($I26=0,"",INDEX('إدخال وسجل المنتجات'!$F$5:$F$590,$I26)) | C26: =IF($I26=0,"",INDEX('إدخال وسجل المنتجات'!$B$5:$B$590,$I26)) | D26: =IF($I26=0,"",INDEX('إدخال وسجل المنتجات'!$C$5:$C$590,$I26)) | E26: =IF($I26=0,"",INDEX('إدخال وسجل المنتجات'!$D$5:$D$590,$I26)) | F26: =IF($I26=0,"",INDEX('إدخال وسجل المنتجات'!$G$5:$G$590,$I26)) | I26: =SUMPRODUCT(('إدخال وسجل المنتجات'!$I$5:$I$590="FRZ")*('إدخال وسجل المنتجات'!$M$5:$M$590=23)*(ROW('إدخال وسجل المنتجات'!$I$5:$I$590)-4)) -> 0 | J26: =IF($I26=0,"",IF($G26="","",$G26*IF(INDEX('إدخال وسجل المنتجات'!$U$5:$U$590,$I26)=0,1,INDEX('إدخال وسجل المنتجات'!$U$5:$U$590,$I26))))
A27: =IF($I27=0,"",24) | B27: =IF($I27=0,"",INDEX('إدخال وسجل المنتجات'!$F$5:$F$590,$I27)) | C27: =IF($I27=0,"",INDEX('إدخال وسجل المنتجات'!$B$5:$B$590,$I27)) | D27: =IF($I27=0,"",INDEX('إدخال وسجل المنتجات'!$C$5:$C$590,$I27)) | E27: =IF($I27=0,"",INDEX('إدخال وسجل المنتجات'!$D$5:$D$590,$I27)) | F27: =IF($I27=0,"",INDEX('إدخال وسجل المنتجات'!$G$5:$G$590,$I27)) | I27: =SUMPRODUCT(('إدخال وسجل المنتجات'!$I$5:$I$590="FRZ")*('إدخال وسجل المنتجات'!$M$5:$M$590=24)*(ROW('إدخال وسجل المنتجات'!$I$5:$I$590)-4)) -> 0 | J27: =IF($I27=0,"",IF($G27="","",$G27*IF(INDEX('إدخال وسجل المنتجات'!$U$5:$U$590,$I27)=0,1,INDEX('إدخال وسجل المنتجات'!$U$5:$U$590,$I27))))
A28: =IF($I28=0,"",25) | B28: =IF($I28=0,"",INDEX('إدخال وسجل المنتجات'!$F$5:$F$590,$I28)) | C28: =IF($I28=0,"",INDEX('إدخال وسجل المنتجات'!$B$5:$B$590,$I28)) | D28: =IF($I28=0,"",INDEX('إدخال وسجل المنتجات'!$C$5:$C$590,$I28)) | E28: =IF($I28=0,"",INDEX('إدخال وسجل المنتجات'!$D$5:$D$590,$I28)) | F28: =IF($I28=0,"",INDEX('إدخال وسجل المنتجات'!$G$5:$G$590,$I28)) | I28: =SUMPRODUCT(('إدخال وسجل المنتجات'!$I$5:$I$590="FRZ")*('إدخال وسجل المنتجات'!$M$5:$M$590=25)*(ROW('إدخال وسجل المنتجات'!$I$5:$I$590)-4)) -> 0 | J28: =IF($I28=0,"",IF($G28="","",$G28*IF(INDEX('إدخال وسجل المنتجات'!$U$5:$U$590,$I28)=0,1,INDEX('إدخال وسجل المنتجات'!$U$5:$U$590,$I28))))
A29: =IF($I29=0,"",26) | B29: =IF($I29=0,"",INDEX('إدخال وسجل المنتجات'!$F$5:$F$590,$I29)) | C29: =IF($I29=0,"",INDEX('إدخال وسجل المنتجات'!$B$5:$B$590,$I29)) | D29: =IF($I29=0,"",INDEX('إدخال وسجل المنتجات'!$C$5:$C$590,$I29)) | E29: =IF($I29=0,"",INDEX('إدخال وسجل المنتجات'!$D$5:$D$590,$I29)) | F29: =IF($I29=0,"",INDEX('إدخال وسجل المنتجات'!$G$5:$G$590,$I29)) | I29: =SUMPRODUCT(('إدخال وسجل المنتجات'!$I$5:$I$590="FRZ")*('إدخال وسجل المنتجات'!$M$5:$M$590=26)*(ROW('إدخال وسجل المنتجات'!$I$5:$I$590)-4)) -> 0 | J29: =IF($I29=0,"",IF($G29="","",$G29*IF(INDEX('إدخال وسجل المنتجات'!$U$5:$U$590,$I29)=0,1,INDEX('إدخال وسجل المنتجات'!$U$5:$U$590,$I29))))
A30: =IF($I30=0,"",27) | B30: =IF($I30=0,"",INDEX('إدخال وسجل المنتجات'!$F$5:$F$590,$I30)) | C30: =IF($I30=0,"",INDEX('إدخال وسجل المنتجات'!$B$5:$B$590,$I30)) | D30: =IF($I30=0,"",INDEX('إدخال وسجل المنتجات'!$C$5:$C$590,$I30)) | E30: =IF($I30=0,"",INDEX('إدخال وسجل المنتجات'!$D$5:$D$590,$I30)) | F30: =IF($I30=0,"",INDEX('إدخال وسجل المنتجات'!$G$5:$G$590,$I30)) | I30: =SUMPRODUCT(('إدخال وسجل المنتجات'!$I$5:$I$590="FRZ")*('إدخال وسجل المنتجات'!$M$5:$M$590=27)*(ROW('إدخال وسجل المنتجات'!$I$5:$I$590)-4)) -> 0 | J30: =IF($I30=0,"",IF($G30="","",$G30*IF(INDEX('إدخال وسجل المنتجات'!$U$5:$U$590,$I30)=0,1,INDEX('إدخال وسجل المنتجات'!$U$5:$U$590,$I30))))
A31: =IF($I31=0,"",28) | B31: =IF($I31=0,"",INDEX('إدخال وسجل المنتجات'!$F$5:$F$590,$I31)) | C31: =IF($I31=0,"",INDEX('إدخال وسجل المنتجات'!$B$5:$B$590,$I31)) | D31: =IF($I31=0,"",INDEX('إدخال وسجل المنتجات'!$C$5:$C$590,$I31)) | E31: =IF($I31=0,"",INDEX('إدخال وسجل المنتجات'!$D$5:$D$590,$I31)) | F31: =IF($I31=0,"",INDEX('إدخال وسجل المنتجات'!$G$5:$G$590,$I31)) | I31: =SUMPRODUCT(('إدخال وسجل المنتجات'!$I$5:$I$590="FRZ")*('إدخال وسجل المنتجات'!$M$5:$M$590=28)*(ROW('إدخال وسجل المنتجات'!$I$5:$I$590)-4)) -> 0 | J31: =IF($I31=0,"",IF($G31="","",$G31*IF(INDEX('إدخال وسجل المنتجات'!$U$5:$U$590,$I31)=0,1,INDEX('إدخال وسجل المنتجات'!$U$5:$U$590,$I31))))
A32: =IF($I32=0,"",29) | B32: =IF($I32=0,"",INDEX('إدخال وسجل المنتجات'!$F$5:$F$590,$I32)) | C32: =IF($I32=0,"",INDEX('إدخال وسجل المنتجات'!$B$5:$B$590,$I32)) | D32: =IF($I32=0,"",INDEX('إدخال وسجل المنتجات'!$C$5:$C$590,$I32)) | E32: =IF($I32=0,"",INDEX('إدخال وسجل المنتجات'!$D$5:$D$590,$I32)) | F32: =IF($I32=0,"",INDEX('إدخال وسجل المنتجات'!$G$5:$G$590,$I32)) | I32: =SUMPRODUCT(('إدخال وسجل المنتجات'!$I$5:$I$590="FRZ")*('إدخال وسجل المنتجات'!$M$5:$M$590=29)*(ROW('إدخال وسجل المنتجات'!$I$5:$I$590)-4)) -> 0 | J32: =IF($I32=0,"",IF($G32="","",$G32*IF(INDEX('إدخال وسجل المنتجات'!$U$5:$U$590,$I32)=0,1,INDEX('إدخال وسجل المنتجات'!$U$5:$U$590,$I32))))
A33: =IF($I33=0,"",30) | B33: =IF($I33=0,"",INDEX('إدخال وسجل المنتجات'!$F$5:$F$590,$I33)) | C33: =IF($I33=0,"",INDEX('إدخال وسجل المنتجات'!$B$5:$B$590,$I33)) | D33: =IF($I33=0,"",INDEX('إدخال وسجل المنتجات'!$C$5:$C$590,$I33)) | E33: =IF($I33=0,"",INDEX('إدخال وسجل المنتجات'!$D$5:$D$590,$I33)) | F33: =IF($I33=0,"",INDEX('إدخال وسجل المنتجات'!$G$5:$G$590,$I33)) | I33: =SUMPRODUCT(('إدخال وسجل المنتجات'!$I$5:$I$590="FRZ")*('إدخال وسجل المنتجات'!$M$5:$M$590=30)*(ROW('إدخال وسجل المنتجات'!$I$5:$I$590)-4)) -> 0 | J33: =IF($I33=0,"",IF($G33="","",$G33*IF(INDEX('إدخال وسجل المنتجات'!$U$5:$U$590,$I33)=0,1,INDEX('إدخال وسجل المنتجات'!$U$5:$U$590,$I33))))
A34: =IF($I34=0,"",31) | B34: =IF($I34=0,"",INDEX('إدخال وسجل المنتجات'!$F$5:$F$590,$I34)) | C34: =IF($I34=0,"",INDEX('إدخال وسجل المنتجات'!$B$5:$B$590,$I34)) | D34: =IF($I34=0,"",INDEX('إدخال وسجل المنتجات'!$C$5:$C$590,$I34)) | E34: =IF($I34=0,"",INDEX('إدخال وسجل المنتجات'!$D$5:$D$590,$I34)) | F34: =IF($I34=0,"",INDEX('إدخال وسجل المنتجات'!$G$5:$G$590,$I34)) | I34: =SUMPRODUCT(('إدخال وسجل المنتجات'!$I$5:$I$590="FRZ")*('إدخال وسجل المنتجات'!$M$5:$M$590=31)*(ROW('إدخال وسجل المنتجات'!$I$5:$I$590)-4)) -> 0 | J34: =IF($I34=0,"",IF($G34="","",$G34*IF(INDEX('إدخال وسجل المنتجات'!$U$5:$U$590,$I34)=0,1,INDEX('إدخال وسجل المنتجات'!$U$5:$U$590,$I34))))
A35: =IF($I35=0,"",32) | B35: =IF($I35=0,"",INDEX('إدخال وسجل المنتجات'!$F$5:$F$590,$I35)) | C35: =IF($I35=0,"",INDEX('إدخال وسجل المنتجات'!$B$5:$B$590,$I35)) | D35: =IF($I35=0,"",INDEX('إدخال وسجل المنتجات'!$C$5:$C$590,$I35)) | E35: =IF($I35=0,"",INDEX('إدخال وسجل المنتجات'!$D$5:$D$590,$I35)) | F35: =IF($I35=0,"",INDEX('إدخال وسجل المنتجات'!$G$5:$G$590,$I35)) | I35: =SUMPRODUCT(('إدخال وسجل المنتجات'!$I$5:$I$590="FRZ")*('إدخال وسجل المنتجات'!$M$5:$M$590=32)*(ROW('إدخال وسجل المنتجات'!$I$5:$I$590)-4)) -> 0 | J35: =IF($I35=0,"",IF($G35="","",$G35*IF(INDEX('إدخال وسجل المنتجات'!$U$5:$U$590,$I35)=0,1,INDEX('إدخال وسجل المنتجات'!$U$5:$U$590,$I35))))
A36: =IF($I36=0,"",33) | B36: =IF($I36=0,"",INDEX('إدخال وسجل المنتجات'!$F$5:$F$590,$I36)) | C36: =IF($I36=0,"",INDEX('إدخال وسجل المنتجات'!$B$5:$B$590,$I36)) | D36: =IF($I36=0,"",INDEX('إدخال وسجل المنتجات'!$C$5:$C$590,$I36)) | E36: =IF($I36=0,"",INDEX('إدخال وسجل المنتجات'!$D$5:$D$590,$I36)) | F36: =IF($I36=0,"",INDEX('إدخال وسجل المنتجات'!$G$5:$G$590,$I36)) | I36: =SUMPRODUCT(('إدخال وسجل المنتجات'!$I$5:$I$590="FRZ")*('إدخال وسجل المنتجات'!$M$5:$M$590=33)*(ROW('إدخال وسجل المنتجات'!$I$5:$I$590)-4)) -> 0 | J36: =IF($I36=0,"",IF($G36="","",$G36*IF(INDEX('إدخال وسجل المنتجات'!$U$5:$U$590,$I36)=0,1,INDEX('إدخال وسجل المنتجات'!$U$5:$U$590,$I36))))
A37: =IF($I37=0,"",34) | B37: =IF($I37=0,"",INDEX('إدخال وسجل المنتجات'!$F$5:$F$590,$I37)) | C37: =IF($I37=0,"",INDEX('إدخال وسجل المنتجات'!$B$5:$B$590,$I37)) | D37: =IF($I37=0,"",INDEX('إدخال وسجل المنتجات'!$C$5:$C$590,$I37)) | E37: =IF($I37=0,"",INDEX('إدخال وسجل المنتجات'!$D$5:$D$590,$I37)) | F37: =IF($I37=0,"",INDEX('إدخال وسجل المنتجات'!$G$5:$G$590,$I37)) | I37: =SUMPRODUCT(('إدخال وسجل المنتجات'!$I$5:$I$590="FRZ")*('إدخال وسجل المنتجات'!$M$5:$M$590=34)*(ROW('إدخال وسجل المنتجات'!$I$5:$I$590)-4)) -> 0 | J37: =IF($I37=0,"",IF($G37="","",$G37*IF(INDEX('إدخال وسجل المنتجات'!$U$5:$U$590,$I37)=0,1,INDEX('إدخال وسجل المنتجات'!$U$5:$U$590,$I37))))
A38: =IF($I38=0,"",35) | B38: =IF($I38=0,"",INDEX('إدخال وسجل المنتجات'!$F$5:$F$590,$I38)) | C38: =IF($I38=0,"",INDEX('إدخال وسجل المنتجات'!$B$5:$B$590,$I38)) | D38: =IF($I38=0,"",INDEX('إدخال وسجل المنتجات'!$C$5:$C$590,$I38)) | E38: =IF($I38=0,"",INDEX('إدخال وسجل المنتجات'!$D$5:$D$590,$I38)) | F38: =IF($I38=0,"",INDEX('إدخال وسجل المنتجات'!$G$5:$G$590,$I38)) | I38: =SUMPRODUCT(('إدخال وسجل المنتجات'!$I$5:$I$590="FRZ")*('إدخال وسجل المنتجات'!$M$5:$M$590=35)*(ROW('إدخال وسجل المنتجات'!$I$5:$I$590)-4)) -> 0 | J38: =IF($I38=0,"",IF($G38="","",$G38*IF(INDEX('إدخال وسجل المنتجات'!$U$5:$U$590,$I38)=0,1,INDEX('إدخال وسجل المنتجات'!$U$5:$U$590,$I38))))
A39: =IF($I39=0,"",36) | B39: =IF($I39=0,"",INDEX('إدخال وسجل المنتجات'!$F$5:$F$590,$I39)) | C39: =IF($I39=0,"",INDEX('إدخال وسجل المنتجات'!$B$5:$B$590,$I39)) | D39: =IF($I39=0,"",INDEX('إدخال وسجل المنتجات'!$C$5:$C$590,$I39)) | E39: =IF($I39=0,"",INDEX('إدخال وسجل المنتجات'!$D$5:$D$590,$I39)) | F39: =IF($I39=0,"",INDEX('إدخال وسجل المنتجات'!$G$5:$G$590,$I39)) | I39: =SUMPRODUCT(('إدخال وسجل المنتجات'!$I$5:$I$590="FRZ")*('إدخال وسجل المنتجات'!$M$5:$M$590=36)*(ROW('إدخال وسجل المنتجات'!$I$5:$I$590)-4)) -> 0 | J39: =IF($I39=0,"",IF($G39="","",$G39*IF(INDEX('إدخال وسجل المنتجات'!$U$5:$U$590,$I39)=0,1,INDEX('إدخال وسجل المنتجات'!$U$5:$U$590,$I39))))
A40: =IF($I40=0,"",37) | B40: =IF($I40=0,"",INDEX('إدخال وسجل المنتجات'!$F$5:$F$590,$I40)) | C40: =IF($I40=0,"",INDEX('إدخال وسجل المنتجات'!$B$5:$B$590,$I40)) | D40: =IF($I40=0,"",INDEX('إدخال وسجل المنتجات'!$C$5:$C$590,$I40)) | E40: =IF($I40=0,"",INDEX('إدخال وسجل المنتجات'!$D$5:$D$590,$I40)) | F40: =IF($I40=0,"",INDEX('إدخال وسجل المنتجات'!$G$5:$G$590,$I40)) | I40: =SUMPRODUCT(('إدخال وسجل المنتجات'!$I$5:$I$590="FRZ")*('إدخال وسجل المنتجات'!$M$5:$M$590=37)*(ROW('إدخال وسجل المنتجات'!$I$5:$I$590)-4)) -> 0 | J40: =IF($I40=0,"",IF($G40="","",$G40*IF(INDEX('إدخال وسجل المنتجات'!$U$5:$U$590,$I40)=0,1,INDEX('إدخال وسجل المنتجات'!$U$5:$U$590,$I40))))
...

Sheet جرد المبرّدة
A1: جرد المنتجات المبرّدة — تخزين مبرد
A2: تاريخ الجرد: __________ القائم بالجرد: __________ (تتحدّث تلقائيًا من السجل) | F2: ="عدد الأصناف: "&COUNTIF('إدخال وسجل المنتجات'!$I$5:$I$590,"CHL") -> عدد الأصناف: 104
A3: م | B3: الكود | C3: اسم المنتج | D3: الاسم EN | E3: الفئة | F3: الوحدة | G3: الكمية الفعلية | H3: ملاحظات | J3: إجمالي الوزن (كجم)
